Workbook
Name APP: 人物卡!$AA$5
Name CON: 人物卡!$U$5
Name DEX: 人物卡!$AA$3
Name EDU: 人物卡!$AG$5
Name INT: 人物卡!$AA$7
Name Luck: 人物卡!$AG$7
Name MP: 人物卡!$W$10
Name POW: 人物卡!$AG$3
Name SIZ: 人物卡!$U$7
Name STR: 人物卡!$U$3
Name COC7_FX_DATA_SHA256: "9b4e824cfc545abc0d5a9ac03f0128371126567df5f718a19fd6a6732c033815"
Name FX_Y1920: '货币汇率'!$V$36:$V$45
Name FX_Y1921: '货币汇率'!$V$46:$V$55
Name FX_Y1922: '货币汇率'!$V$56:$V$65
Name FX_Y1923: '货币汇率'!$V$66:$V$74
Name FX_Y1924: '货币汇率'!$V$75:$V$84
Name FX_Y1925: '货币汇率'!$V$85:$V$94
Name FX_Y1926: '货币汇率'!$V$95:$V$104
Name FX_Y1927: '货币汇率'!$V$105:$V$115
Name FX_Y1928: '货币汇率'!$V$116:$V$126
Name FX_Y1929: '货币汇率'!$V$127:$V$137
Name FX_Y1930: '货币汇率'!$V$138:$V$148
Name FX_Y1931: '货币汇率'!$V$149:$V$159
Name FX_Y1932: '货币汇率'!$V$160:$V$170
Name FX_Y1933: '货币汇率'!$V$171:$V$181
Name FX_Y1934: '货币汇率'!$V$182:$V$192
Name FX_Y1935: '货币汇率'!$V$193:$V$203
Name FX_Y1936: '货币汇率'!$V$204:$V$214
Name FX_Y1937: '货币汇率'!$V$215:$V$225
Name FX_Y1938: '货币汇率'!$V$226:$V$236
Name FX_Y1939: '货币汇率'!$V$237:$V$247
Name FX_Y1940: '货币汇率'!$V$248:$V$258
Name FX_Y1941: '货币汇率'!$V$259:$V$268
Name FX_Y1942: '货币汇率'!$V$269:$V$272
Name FX_Y1943: '货币汇率'!$V$273:$V$276
Name FX_Y1944: '货币汇率'!$V$277:$V$280
Name FX_Y1945: '货币汇率'!$V$281:$V$284
Name FX_Y1946: '货币汇率'!$V$285:$V$290
Name FX_Y1947: '货币汇率'!$V$291:$V$296
Name FX_Y1948: '货币汇率'!$V$297:$V$302
Name FX_Y1949: '货币汇率'!$V$303:$V$307
Name FX_Y1950: '货币汇率'!$V$308:$V$317
Name FX_Y1951: '货币汇率'!$V$318:$V$327
Name FX_Y1952: '货币汇率'!$V$328:$V$338
Name FX_Y1953: '货币汇率'!$V$339:$V$349
Name FX_Y1954: '货币汇率'!$V$350:$V$360
Name FX_Y1955: '货币汇率'!$V$361:$V$371
Name FX_Y1956: '货币汇率'!$V$372:$V$382
Name FX_Y1957: '货币汇率'!$V$383:$V$393
Name FX_Y1958: '货币汇率'!$V$394:$V$404
Name FX_Y1959: '货币汇率'!$V$405:$V$415
Name FX_Y1960: '货币汇率'!$V$416:$V$426
Name FX_Y1961: '货币汇率'!$V$427:$V$437
Name FX_Y1962: '货币汇率'!$V$438:$V$448
Name FX_Y1963: '货币汇率'!$V$449:$V$459
Name FX_Y1964: '货币汇率'!$V$460:$V$470
Name FX_Y1965: '货币汇率'!$V$471:$V$481
Name FX_Y1966: '货币汇率'!$V$482:$V$492
Name FX_Y1967: '货币汇率'!$V$493:$V$503
Name FX_Y1968: '货币汇率'!$V$504:$V$514

Sheet 人物卡
B1: 电脑推荐使用excel2010及以后版本或WPS打开本卡，使用横轴滚动条可以看见更多东西
B2: 调查员信息 | S2: 年龄补正： | V2: =附表!D37 -> 请和kp商议 | AA2: 属性 | AC2: 已用点数: | AG2: =U3+U5+U7+AA3+AA5+AA7+AG3+AG5+AG7 -> 0 | AL2: 调查员肖像 | AU2: 您的角色可能（只是可能！）
B3: 姓名 | S3: 力量 STR | W3: =INT(U3/2) -> 0 | Y3: 敏捷 DEX | AC3: =INT(AA3/2) -> 0 | AE3: 意志 POW | AI3: =INT(AG3/2) -> 0 | AU3: =IF(U3=0,"",IF(U3<=15,"虚弱，孱弱",IF(U3<=40,"力量弱小",IF(U3<=60,"有正常人的力量",IF(U3<=80,"超乎常人的力量",IF(U3<100,"超乎超乎常人的力量")))))) | BC3: =IF(AA3=0,"",IF(AA3<=20,"很不灵活",IF(AA3<=40,"不是很灵活",IF(AA3<=60,"普通人水平",IF(AA3<=80,"是一位运动健将",IF(AA3<100,"高速而灵活,可以达成超凡的技艺")))))) | BK3: =IF(AG3=0,"",IF(AG3<=20,"尔不过玩物",IF(AG3<=40,"痴愚盲目",IF(AG3<=60,"如常人一般会有一定自制力",IF(AG3<=80,"我心如铁，心坚石穿",IF(AG3<100,"泰山崩于面而色不变",IF(AG3<140,"钢铁之心，还能看见鬼","你怕是个假人吧")))))))
B4: 玩家 | J4: 时代 | M4: 1920s | W4: =INT(U3/5) -> 0 | AC4: =INT(AA3/5) -> 0 | AI4: =INT(AG3/5) -> 0
B5: 职业 | J5: 职业序号 | M5: 1 | S5: 体质 CON | W5: =INT(U5/2) -> 0 | Y5: 外貌 APP | AC5: =INT(AA5/2) -> 0 | AE5: 教育 知识 | AI5: =INT(AG5/2) -> 0 | AU5: =IF(U5=0,"",IF(U5<=20,"常年患病在身",IF(U5<=40,"体弱多病",IF(U5<=60,"不会生什么大毛病",IF(U5<=80,"健硕，浑身湿透也不会感冒",IF(U5<100,"身体素质极好，精神抖擞")))))) | BC5: =IF(AA5=0,"",IF(AA5<=20,"用脸就能恐惧敌人。。或队友",IF(AA5<=40,"有些难看",IF(AA5<=60,"人群之中谁也不会看你一眼之后就忘不掉你容颜",IF(AA5<=80,"五官端正，仪表堂堂",IF(AA5<100,"沉鱼落雁，闭月羞花")))))) | BK5: =IF(AG5=0,"",IF(AG5<=20,"目不识丁",IF(AG5<=40,"小学毕业",IF(AG5<=60,"高中毕业",IF(AG5<=80,"是重点大学的学生，或是普通大学的研究生",IF(AG5<100,"饱读诗书，满腹经纶"))))))
B6: 年龄 | J6: 性别 | W6: =INT(U5/5) -> 0 | AC6: =INT(AA5/5) -> 0 | AI6: =INT(AG5/5) -> 0
B7: 住地 | J7: 故乡 | S7: 体型 SIZ | W7: =INT(U7/2) -> 0 | Y7: 智力 灵感 | AC7: =INT(AA7/2) -> 0 | AE7: 幸运 Luck | AI7: =INT(AG7/2) -> 0 | AU7: =IF(U7=0,"",IF(U7<=20,"孩童，身短体瘦",IF(U7<=40,"乙女身材",IF(U7<=60,"普遍身高155-175",IF(U7<=80,"不是高就是胖",IF(U7<=100,"大号的人",IF(U7<150,"听说你正在申请身高世界记录？",IF(U7<180,"你可能是一头牛",IF(U7<200,"你已经是历史上最重的人类了","过分了喂！"))))))))) | BC7: =IF(INT=0,"",IF(INT<=20,"脑子是个好东西，可惜。。。",IF(INT<=40,"理解知识要耗费比普通人更多的时间",IF(INT<=60,"有着普通人的灵光一现",IF(INT<=80,"可以自主进行发明创造",IF(INT<100,"天才级水准")))))) | BK7: =IF(Luck=0,"",IF(Luck<=20,"克夫克妻",IF(Luck<=40,"霉运连连",IF(Luck<=60,"命格平庸",IF(Luck<=80,"在马路边捡到100块",IF(Luck<100,"被幸运女神所眷顾"))))))
B8: 现时间 | E8: 公元 | G8: 2026 | J8: 1月 | L8: 1日 | N8: 0：00 | W8: =INT(U7/5) -> 0 | AC8: =INT(AA7/5) -> 0 | AI8: =INT(AG7/5) -> 0
B9: =IF(F9=0,"","任意特长数：") | F9: =INDEX(本职技能!$A$2:$HX$69,MATCH("任意特长",本职技能!$A$2:$A$75,0),MATCH($M$5,本职技能!$A$1:$HX$1,0)) -> 0 | K9: =INDEX(本职技能!$A$2:$HX$69,MATCH("☆",本职技能!$A$2:$A$75,0),MATCH($M$5,本职技能!$A$1:$HX$1,0)) -> 0 | T9: =INDEX(本职技能!$A$2:$HX$69,MATCH("⊙",本职技能!$A$2:$A$75,0),MATCH($M$5,本职技能!$A$1:$HX$1,0)) -> 0 | AC9: =INDEX(本职技能!$A$2:$HX$69,MATCH("☯",本职技能!$A$2:$A$75,0),MATCH($M$5,本职技能!$A$1:$HX$1,0)) -> 0 | AL9: =INDEX(本职技能!$A$2:$HX$69,MATCH("※",本职技能!$A$2:$A$75,0),MATCH($M$5,本职技能!$A$1:$HX$1,0)) -> 0
B10: 生命值 Hit Points | E10: =G10 -> 0 | G10: =INT((U5+U7)/10) -> 0 | I10: 状态: | K10: 理智 Sanity | N10: 0 | P10: =INT(POW) -> 0 | R10: 状态: | T10: 魔法 Magic Points | W10: 0 | Y10: =INT(AG3/5) -> 0 | AA10: 每h恢复 | AC10: 移动力 MOV | AF10: =AI11+8 -> 8 | AI10: 调整值 | AK10: 护甲 Armor | AN10: =IF($AN12=0,"0",VLOOKUP($AN12,'防具表 载具表'!B2:J82,2,FALSE)) -> 无 | AP10: 覆盖部位
I11: 健康 | R11: 清醒 | AA11: =IF(AG3="","",INT(AG3/100+1)) | AI11: =附表!C9 -> 0 | AP11: =IF($AN12=0,"",VLOOKUP($AN12,'防具表 载具表'!B2:I101,4,FALSE)) -> ——
B12: 重伤值: | D12: =CEILING(G10/2,1) -> 0 | F12: 临时生命值： | I12: 0 | K12: 今日损失 : | N12: 0 | P12: 临时疯狂 | R12: =P10/10 -> 0 | T12: 用过的魔法： | AC12: 移动方式 | AE12: 步式 | AG12: 护甲减值 | AI12: 关 | AK12: 护甲类型 : | AN12: 请看【防具表】
B13: =IF(M5=0," ","["&LOOKUP(M5,职业列表!A2:A232,职业列表!B2:B232)&"]的本职技能："&LOOKUP(M5,职业列表!A2:A232,职业列表!G2:G232)) -> [自定义职业]的本职技能：不多于8个本职技能。在右侧职业属性中输入第二职业属性的数值（留空则视为EDU）并自行设置起始信誉。使用自定义职业前，请先咨询你的守秘人。
B14: 技能表（成长点数与经历包点分别填写；经历包额度不含成长）
A15: 提示 | B15: 成功标 | D15: 本职 | F15: 技能名称 | J15: 初始 | L15: 成长 点数 | M15: 经历 包点 | N15: 职业 | P15: 兴趣 | R15: 成功率 普通/困难/极难 | X15: 成功标 | Z15: 本职 | AB15: 技能名称 | AF15: 初始 | AH15: 成长 点数 | AI15: 经历 包点 | AJ15: 职业 | AL15: 兴趣 | AN15: 成功率 普通/困难/极难 | AT15: 提示
A16: =IF(AND(IFERROR(N16>0,FALSE),IFERROR(P16>0,FALSE)),"混点！ ","")&IF(AND(IFERROR(N16>0,FALSE),D16<>"★"),"非本职职业！","") | B16: ☐ | D16: =IFERROR(IF(ISTEXT(IFERROR(VLOOKUP(人物卡!F16,人物卡!BJ18:BR22,1,FALSE),IFERROR(VLOOKUP(人物卡!F16,人物卡!BA18:BC22,1,FALSE),0))),"★",INDEX(本职技能!$A$2:$HX$76,MATCH(人物卡!F16,本职技能!$A$2:$A$75,0),MATCH(人物卡!$M$5,本职技能!$A$1:$HX$1,0))),0) | F16: 会计 | J16: 5 | R16: =SUM(J16:Q16) -> 5 | T16: =INT(R16/2) -> 2 | V16: =INT(R16/5) -> 1 | X16: ☐ | Z16: =IFERROR(IF(ISTEXT(IFERROR(VLOOKUP(人物卡!AB16,人物卡!BJ18:BR22,1,FALSE),IFERROR(VLOOKUP(人物卡!AB16,人物卡!BA18:BC22,1,FALSE),0))),"★",INDEX(本职技能!$A$2:$HX$76,MATCH(人物卡!AB16,本职技能!$A$2:$A$75,0),MATCH(人物卡!$M$5,本职技能!$A$1:$HX$1,0))),0) | AB16: 法律 | AF16: 5 | AN16: =SUM(AF16:AM16) -> 5 | AP16: =INT(AN16/2) -> 2 | AR16: =INT(AN16/5) -> 1 | AT16: =IF(AND(IFERROR(AJ16>0,FALSE),IFERROR(AL16>0,FALSE)),"混点！ ","")&IF(AND(IFERROR(AJ16>0,FALSE),Z16<>"★"),"非本职！","")
A17: =IF(AND(IFERROR(N17>0,FALSE),IFERROR(P17>0,FALSE)),"混点！ ","")&IF(AND(IFERROR(N17>0,FALSE),D17<>"★"),"非本职职业！","") | B17: ☐ | D17: =IFERROR(IF(ISTEXT(IFERROR(VLOOKUP(人物卡!F17,人物卡!BJ18:BR22,1,FALSE),IFERROR(VLOOKUP(人物卡!F17,人物卡!BA18:BC22,1,FALSE),0))),"★",INDEX(本职技能!$A$2:$HX$76,MATCH(人物卡!F17,本职技能!$A$2:$A$75,0),MATCH(人物卡!$M$5,本职技能!$A$1:$HX$1,0))),0) | F17: 人类学 | J17: 1 | R17: =SUM(J17:Q17) -> 1 | T17: =INT(R17/2) -> 0 | V17: =INT(R17/5) -> 0 | X17: ☐ | Z17: =IFERROR(IF(ISTEXT(IFERROR(VLOOKUP(人物卡!AB17,人物卡!BJ18:BR22,1,FALSE),IFERROR(VLOOKUP(人物卡!AB17,人物卡!BA18:BC22,1,FALSE),0))),"★",INDEX(本职技能!$A$2:$HX$76,MATCH(人物卡!AB17,本职技能!$A$2:$A$75,0),MATCH(人物卡!$M$5,本职技能!$A$1:$HX$1,0))),0) | AB17: 图书馆使用 | AF17: 20 | AN17: =SUM(AF17:AM17) -> 20 | AP17: =INT(AN17/2) -> 10 | AR17: =INT(AN17/5) -> 4 | AT17: =IF(AND(IFERROR(AJ17>0,FALSE),IFERROR(AL17>0,FALSE)),"混点！ ","")&IF(AND(IFERROR(AJ17>0,FALSE),Z17<>"★"),"非本职！","") | AU17: 你现在有这么多 | BA17: 那么你分配到了哪里?
A18: =IF(AND(IFERROR(N18>0,FALSE),IFERROR(P18>0,FALSE)),"混点！ ","")&IF(AND(IFERROR(N18>0,FALSE),D18<>"★"),"非本职职业！","") | B18: ☐ | D18: =IFERROR(IF(ISTEXT(IFERROR(VLOOKUP(人物卡!F18,人物卡!BJ18:BR22,1,FALSE),IFERROR(VLOOKUP(人物卡!F18,人物卡!BA18:BC22,1,FALSE),0))),"★",INDEX(本职技能!$A$2:$HX$76,MATCH(人物卡!F18,本职技能!$A$2:$A$75,0),MATCH(人物卡!$M$5,本职技能!$A$1:$HX$1,0))),0) | F18: 估价 | J18: 5 | R18: =SUM(J18:Q18) -> 5 | T18: =INT(R18/2) -> 2 | V18: =INT(R18/5) -> 1 | X18: ☐ | Z18: =IFERROR(IF(ISTEXT(IFERROR(VLOOKUP(人物卡!AB18,人物卡!BJ18:BR22,1,FALSE),IFERROR(VLOOKUP(人物卡!AB18,人物卡!BA18:BC22,1,FALSE),0))),"★",INDEX(本职技能!$A$2:$HX$76,MATCH(人物卡!AB18,本职技能!$A$2:$A$75,0),MATCH(人物卡!$M$5,本职技能!$A$1:$HX$1,0))),0) | AB18: 聆听 | AF18: 20 | AN18: =SUM(AF18:AM18) -> 20 | AP18: =INT(AN18/2) -> 10 | AR18: =INT(AN18/5) -> 4 | AT18: =IF(AND(IFERROR(AJ18>0,FALSE),IFERROR(AL18>0,FALSE)),"混点！ ","")&IF(AND(IFERROR(AJ18>0,FALSE),Z18<>"★"),"非本职！","") | AU18: 任意特长
A19: =IF(AND(IFERROR(N19>0,FALSE),IFERROR(P19>0,FALSE)),"混点！ ","")&IF(AND(IFERROR(N19>0,FALSE),D19<>"★"),"非本职职业！","") | B19: ☐ | D19: =IFERROR(IF(ISTEXT(IFERROR(VLOOKUP(人物卡!F19,人物卡!BJ18:BR22,1,FALSE),IFERROR(VLOOKUP(人物卡!F19,人物卡!BA18:BC22,1,FALSE),0))),"★",INDEX(本职技能!$A$2:$HX$76,MATCH(人物卡!F19,本职技能!$A$2:$A$75,0),MATCH(人物卡!$M$5,本职技能!$A$1:$HX$1,0))),0) | F19: 考古学 | J19: 1 | R19: =SUM(J19:Q19) -> 1 | T19: =INT(R19/2) -> 0 | V19: =INT(R19/5) -> 0 | X19: ☐ | Z19: =IFERROR(IF(ISTEXT(IFERROR(VLOOKUP(人物卡!AB19,人物卡!BJ18:BR22,1,FALSE),IFERROR(VLOOKUP(人物卡!AB19,人物卡!BA18:BC22,1,FALSE),0))),"★",INDEX(本职技能!$A$2:$HX$76,MATCH(人物卡!AB19,本职技能!$A$2:$A$75,0),MATCH(人物卡!$M$5,本职技能!$A$1:$HX$1,0))),0) | AB19: 锁匠 | AF19: 1 | AN19: =SUM(AF19:AM19) -> 1 | AP19: =INT(AN19/2) -> 0 | AR19: =INT(AN19/5) -> 0 | AT19: =IF(AND(IFERROR(AJ19>0,FALSE),IFERROR(AL19>0,FALSE)),"混点！ ","")&IF(AND(IFERROR(AJ19>0,FALSE),Z19<>"★"),"非本职职业！","") | AU19: =附表!AD25 -> 无
A20: =IF(AND(IFERROR(N20>0,FALSE),IFERROR(P20>0,FALSE)),"混点！ ","")&IF(AND(IFERROR(N20>0,FALSE),D20<>"★"),"非本职职业！","") | B20: ☐ | D20: =IFERROR(IF(ISTEXT(IFERROR(VLOOKUP(人物卡!F20,人物卡!BJ18:BR22,1,FALSE),IFERROR(VLOOKUP(人物卡!F20,人物卡!BA18:BC22,1,FALSE),0))),"★",INDEX(本职技能!$A$2:$HX$76,MATCH(人物卡!F20,本职技能!$A$2:$A$75,0),MATCH(人物卡!$M$5,本职技能!$A$1:$HX$1,0))),0) | F20: 技艺① | J20: =IF(ISBLANK(AU26),5,IF(H20=AU26,BA26,5)) -> 5 | R20: =SUM(J20:Q20) -> 5 | T20: =INT(R20/2) -> 2 | V20: =INT(R20/5) -> 1 | X20: ☐ | Z20: =IFERROR(IF(ISTEXT(IFERROR(VLOOKUP(人物卡!AB20,人物卡!BJ18:BR22,1,FALSE),IFERROR(VLOOKUP(人物卡!AB20,人物卡!BA18:BC22,1,FALSE),0))),"★",INDEX(本职技能!$A$2:$HX$76,MATCH(人物卡!AB20,本职技能!$A$2:$A$75,0),MATCH(人物卡!$M$5,本职技能!$A$1:$HX$1,0))),0) | AB20: 机械维修 | AF20: 10 | AN20: =SUM(AF20:AM20) -> 10 | AP20: =INT(AN20/2) -> 5 | AR20: =INT(AN20/5) -> 2 | AT20: =IF(AND(IFERROR(AJ20>0,FALSE),IFERROR(AL20>0,FALSE)),"混点！ ","")&IF(AND(IFERROR(AJ20>0,FALSE),Z20<>"★"),"非本职职业！","")
A21: =IF(AND(IFERROR(N21>0,FALSE),IFERROR(P21>0,FALSE)),"混点！ ","")&IF(AND(IFERROR(N21>0,FALSE),D21<>"★"),"非本职职业！","") | B21: ☐ | D21: =IFERROR(IF(ISTEXT(IFERROR(VLOOKUP(人物卡!F21,人物卡!BJ18:BR22,1,FALSE),IFERROR(VLOOKUP(人物卡!F21,人物卡!BA18:BC22,1,FALSE),0))),"★",INDEX(本职技能!$A$2:$HX$76,MATCH(人物卡!F21,本职技能!$A$2:$A$75,0),MATCH(人物卡!$M$5,本职技能!$A$1:$HX$1,0))),0) | F21: 技艺② | J21: =IF(ISBLANK(AU26),5,IF(H21=AU26,BA26,5)) -> 5 | R21: =SUM(J21:Q21) -> 5 | T21: =INT(R21/2) -> 2 | V21: =INT(R21/5) -> 1 | X21: ☐ | Z21: =IFERROR(IF(ISTEXT(IFERROR(VLOOKUP(人物卡!AB21,人物卡!BJ18:BR22,1,FALSE),IFERROR(VLOOKUP(人物卡!AB21,人物卡!BA18:BC22,1,FALSE),0))),"★",INDEX(本职技能!$A$2:$HX$76,MATCH(人物卡!AB21,本职技能!$A$2:$A$75,0),MATCH(人物卡!$M$5,本职技能!$A$1:$HX$1,0))),0) | AB21: 医学 | AF21: 1 | AN21: =SUM(AF21:AM21) -> 1 | AP21: =INT(AN21/2) -> 0 | AR21: =INT(AN21/5) -> 0 | AT21: =IF(AND(IFERROR(AJ21>0,FALSE),IFERROR(AL21>0,FALSE)),"混点！ ","")&IF(AND(IFERROR(AJ21>0,FALSE),Z21<>"★"),"非本职职业！","")
A22: =IF(AND(IFERROR(N22>0,FALSE),IFERROR(P22>0,FALSE)),"混点！ ","")&IF(AND(IFERROR(N22>0,FALSE),D22<>"★"),"非本职职业！","") | B22: ☐ | D22: =IFERROR(IF(ISTEXT(IFERROR(VLOOKUP(人物卡!F22,人物卡!BJ18:BR22,1,FALSE),IFERROR(VLOOKUP(人物卡!F22,人物卡!BA18:BC22,1,FALSE),0))),"★",INDEX(本职技能!$A$2:$HX$76,MATCH(人物卡!F22,本职技能!$A$2:$A$75,0),MATCH(人物卡!$M$5,本职技能!$A$1:$HX$1,0))),0) | F22: 技艺③ | J22: =IF(ISBLANK(AU26),5,IF(H22=AU26,BA26,5)) -> 5 | R22: =SUM(J22:Q22) -> 5 | T22: =INT(R22/2) -> 2 | V22: =INT(R22/5) -> 1 | X22: ☐ | Z22: =IFERROR(IF(ISTEXT(IFERROR(VLOOKUP(人物卡!AB22,人物卡!BJ18:BR22,1,FALSE),IFERROR(VLOOKUP(人物卡!AB22,人物卡!BA18:BC22,1,FALSE),0))),"★",INDEX(本职技能!$A$2:$HX$76,MATCH(人物卡!AB22,本职技能!$A$2:$A$75,0),MATCH(人物卡!$M$5,本职技能!$A$1:$HX$1,0))),0) | AB22: 博物学 | AF22: 10 | AN22: =SUM(AF22:AM22) -> 10 | AP22: =INT(AN22/2) -> 5 | AR22: =INT(AN22/5) -> 2 | AT22: =IF(AND(IFERROR(AJ22>0,FALSE),IFERROR(AL22>0,FALSE)),"混点！ ","")&IF(AND(IFERROR(AJ22>0,FALSE),Z22<>"★"),"非本职职业！","") | AU22: 提示当前职业
A23: =IF(AND(IFERROR(N23>0,FALSE),IFERROR(P23>0,FALSE)),"混点！ ","")&IF(AND(IFERROR(N23>0,FALSE),D23<>"★"),"非本职职业！","") | B23: ☐ | D23: =IFERROR(IF(ISTEXT(IFERROR(VLOOKUP(人物卡!F23,人物卡!BJ18:BR22,1,FALSE),IFERROR(VLOOKUP(人物卡!F23,人物卡!BA18:BC22,1,FALSE),0))),"★",INDEX(本职技能!$A$2:$HX$76,MATCH(人物卡!F23,本职技能!$A$2:$A$75,0),MATCH(人物卡!$M$5,本职技能!$A$1:$HX$1,0))),0) | F23: 取悦 | J23: 15 | R23: =SUM(J23:Q23) -> 15 | T23: =INT(R23/2) -> 7 | V23: =INT(R23/5) -> 3 | X23: ☐ | Z23: =IFERROR(IF(ISTEXT(IFERROR(VLOOKUP(人物卡!AB23,人物卡!BJ18:BR22,1,FALSE),IFERROR(VLOOKUP(人物卡!AB23,人物卡!BA18:BC22,1,FALSE),0))),"★",INDEX(本职技能!$A$2:$HX$76,MATCH(人物卡!AB23,本职技能!$A$2:$A$75,0),MATCH(人物卡!$M$5,本职技能!$A$1:$HX$1,0))),0) | AB23: 导航 | AF23: 10 | AN23: =SUM(AF23:AM23) -> 10 | AP23: =INT(AN23/2) -> 5 | AR23: =INT(AN23/5) -> 2 | AT23: =IF(AND(IFERROR(AJ23>0,FALSE),IFERROR(AL23>0,FALSE)),"混点！ ","")&IF(AND(IFERROR(AJ23>0,FALSE),Z23<>"★"),"非本职职业！","") | AU23: 请将你选择的任意特长写在上方栏内，这样既方便你写卡又方便KP审卡
A24: =IF(AND(IFERROR(N24>0,FALSE),IFERROR(P24>0,FALSE)),"混点！ ","")&IF(AND(IFERROR(N24>0,FALSE),D24<>"★"),"非本职职业！","") | B24: ☐ | D24: =IFERROR(IF(ISTEXT(IFERROR(VLOOKUP(人物卡!F24,人物卡!BJ18:BR22,1,FALSE),IFERROR(VLOOKUP(人物卡!F24,人物卡!BA18:BC22,1,FALSE),0))),"★",INDEX(本职技能!$A$2:$HX$76,MATCH(人物卡!F24,本职技能!$A$2:$A$75,0),MATCH(人物卡!$M$5,本职技能!$A$1:$HX$1,0))),0) | F24: 攀爬 | J24: 20 | R24: =SUM(J24:Q24) -> 20 | T24: =INT(R24/2) -> 10 | V24: =INT(R24/5) -> 4 | X24: ☐ | Z24: =IFERROR(IF(ISTEXT(IFERROR(VLOOKUP(人物卡!AB24,人物卡!BJ18:BR22,1,FALSE),IFERROR(VLOOKUP(人物卡!AB24,人物卡!BA18:BC22,1,FALSE),0))),"★",INDEX(本职技能!$A$2:$HX$76,MATCH(人物卡!AB24,本职技能!$A$2:$A$75,0),MATCH(人物卡!$M$5,本职技能!$A$1:$HX$1,0))),0) | AB24: 神秘学 | AF24: 5 | AN24: =SUM(AF24:AM24) -> 5 | AP24: =INT(AN24/2) -> 2 | AR24: =INT(AN24/5) -> 1 | AT24: =IF(AND(IFERROR(AJ24>0,FALSE),IFERROR(AL24>0,FALSE)),"混点！ ","")&IF(AND(IFERROR(AJ24>0,FALSE),Z24<>"★"),"非本职职业！","") | AU24: 自定义子技能 | BC24: 自定义经历包 | BK24: 自定义状态
A25: =IF(AND(IFERROR(N25>0,FALSE),IFERROR(P25>0,FALSE)),"混点！ ","")&IF(AND(IFERROR(N25>0,FALSE),D25<>"★"),"非本职职业！","") | B25: ☐ | D25: =IFERROR(IF(ISTEXT(IFERROR(VLOOKUP(人物卡!F25,人物卡!BJ18:BR22,1,FALSE),IFERROR(VLOOKUP(人物卡!F25,人物卡!BA18:BC22,1,FALSE),0))),"★",INDEX(本职技能!$A$2:$HX$76,MATCH(人物卡!F25,本职技能!$A$2:$A$75,0),MATCH(人物卡!$M$5,本职技能!$A$1:$HX$1,0))),0) | F25: 计算机使用 Ω | J25: 5 | R25: =SUM(J25:Q25) -> 5 | T25: =INT(R25/2) -> 2 | V25: =INT(R25/5) -> 1 | X25: ☐ | Z25: =IFERROR(IF(ISTEXT(IFERROR(VLOOKUP(人物卡!AB25,人物卡!BJ18:BR22,1,FALSE),IFERROR(VLOOKUP(人物卡!AB25,人物卡!BA18:BC22,1,FALSE),0))),"★",INDEX(本职技能!$A$2:$HX$76,MATCH(人物卡!AB25,本职技能!$A$2:$A$75,0),MATCH(人物卡!$M$5,本职技能!$A$1:$HX$1,0))),0) | AB25: 操作重型机械 | AF25: 1 | AN25: =SUM(AF25:AM25) -> 1 | AP25: =INT(AN25/2) -> 0 | AR25: =INT(AN25/5) -> 0 | AT25: =IF(AND(IFERROR(AJ25>0,FALSE),IFERROR(AL25>0,FALSE)),"混点！ ","")&IF(AND(IFERROR(AJ25>0,FALSE),Z25<>"★"),"非本职职业！","") | AU25: 技艺技能名称 | BA25: 基础值 | BC25: 经历包名称 | BK25: 状态名称(例:生病、精神分裂)
A26: =IF(AND(IFERROR(N26>0,FALSE),IFERROR(P26>0,FALSE)),"混点！ ","")&IF(AND(IFERROR(N26>0,FALSE),D26<>"★"),"非本职职业！","") | B26: —— | D26: ★ | F26: 信用评级 | J26: 0 | R26: =SUM(J26:Q26) -> 0 | T26: =INT(R26/2) -> 0 | V26: =INT(R26/5) -> 0 | X26: ☐ | Z26: =IFERROR(IF(ISTEXT(IFERROR(VLOOKUP(人物卡!AB26,人物卡!BJ18:BR22,1,FALSE),IFERROR(VLOOKUP(人物卡!AB26,人物卡!BA18:BC22,1,FALSE),0))),"★",INDEX(本职技能!$A$2:$HX$76,MATCH(人物卡!AB26,本职技能!$A$2:$A$75,0),MATCH(人物卡!$M$5,本职技能!$A$1:$HX$1,0))),0) | AB26: 说服 | AF26: 10 | AN26: =SUM(AF26:AM26) -> 10 | AP26: =INT(AN26/2) -> 5 | AR26: =INT(AN26/5) -> 2 | AT26: =IF(AND(IFERROR(AJ26>0,FALSE),IFERROR(AL26>0,FALSE)),"混点！ ","")&IF(AND(IFERROR(AJ26>0,FALSE),Z26<>"★"),"非本职职业！","")
B27: —— | D27: =IFERROR(IF(ISTEXT(IFERROR(VLOOKUP(F27,人物卡!BJ18:BR22,1,FALSE),IFERROR(VLOOKUP(F27,人物卡!BA18:BC22,1,FALSE),0))),"★",INDEX(本职技能!$A$2:$HX$76,MATCH(F27,本职技能!$A$2:$A$75,0),MATCH(人物卡!$M$5,本职技能!$A$1:$HX$1,0))),0) | F27: 克苏鲁神话 | J27: 0 | N27: —— | P27: —— | R27: =SUM(J27:Q27) -> 0 | T27: =INT(R27/2) -> 0 | V27: =INT(R27/5) -> 0 | X27: ☐ | Z27: =IFERROR(IF(ISTEXT(IFERROR(VLOOKUP(人物卡!AB27,人物卡!BJ18:BR22,1,FALSE),IFERROR(VLOOKUP(人物卡!AB27,人物卡!BA18:BC22,1,FALSE),0))),"★",INDEX(本职技能!$A$2:$HX$76,MATCH(人物卡!AB27,本职技能!$A$2:$A$75,0),MATCH(人物卡!$M$5,本职技能!$A$1:$HX$1,0))),0) | AB27: 驾驶： | AF27: =IF(ISBLANK(AU32),1,IF(AD27=AU32,BA32,1)) -> 1 | AN27: =SUM(AF27:AM27) -> 1 | AP27: =INT(AN27/2) -> 0 | AR27: =INT(AN27/5) -> 0 | AT27: =IF(AND(IFERROR(AJ27>0,FALSE),IFERROR(AL27>0,FALSE)),"混点！ ","")&IF(AND(IFERROR(AJ27>0,FALSE),Z27<>"★"),"非本职职业！","") | AU27: 格斗技能名称 | BA27: 基础值 | BC27: san值减少 | BG27: 技能增长 | BK27: 身体状态 | BO27: 精神状态
A28: =IF(AND(IFERROR(N28>0,FALSE),IFERROR(P28>0,FALSE)),"混点！ ","")&IF(AND(IFERROR(N28>0,FALSE),D28<>"★"),"非本职职业！","") | B28: ☐ | D28: =IFERROR(IF(ISTEXT(IFERROR(VLOOKUP(人物卡!F28,人物卡!BJ18:BR22,1,FALSE),IFERROR(VLOOKUP(人物卡!F28,人物卡!BA18:BC22,1,FALSE),0))),"★",INDEX(本职技能!$A$2:$HX$76,MATCH(人物卡!F28,本职技能!$A$2:$A$75,0),MATCH(人物卡!$M$5,本职技能!$A$1:$HX$1,0))),0) | F28: 乔装 | J28: 5 | R28: =SUM(J28:Q28) -> 5 | T28: =INT(R28/2) -> 2 | V28: =INT(R28/5) -> 1 | X28: ☐ | Z28: =IFERROR(IF(ISTEXT(IFERROR(VLOOKUP(人物卡!AB28,人物卡!BJ18:BR22,1,FALSE),IFERROR(VLOOKUP(人物卡!AB28,人物卡!BA18:BC22,1,FALSE),0))),"★",INDEX(本职技能!$A$2:$HX$76,MATCH(人物卡!AB28,本职技能!$A$2:$A$75,0),MATCH(人物卡!$M$5,本职技能!$A$1:$HX$1,0))),0) | AB28: 精神分析 | AF28: 1 | AN28: =SUM(AF28:AM28) -> 1 | AP28: =INT(AN28/2) -> 0 | AR28: =INT(AN28/5) -> 0 | AT28: =IF(AND(IFERROR(AJ28>0,FALSE),IFERROR(AL28>0,FALSE)),"混点！ ","")&IF(AND(IFERROR(AJ28>0,FALSE),Z28<>"★"),"非本职职业！","")
A29: =IF(AND(IFERROR(N29>0,FALSE),IFERROR(P29>0,FALSE)),"混点！ ","")&IF(AND(IFERROR(N29>0,FALSE),D29<>"★"),"非本职职业！","") | B29: ☐ | D29: =IFERROR(IF(ISTEXT(IFERROR(VLOOKUP(人物卡!F29,人物卡!BJ18:BR22,1,FALSE),IFERROR(VLOOKUP(人物卡!F29,人物卡!BA18:BC22,1,FALSE),0))),"★",INDEX(本职技能!$A$2:$HX$76,MATCH(人物卡!F29,本职技能!$A$2:$A$75,0),MATCH(人物卡!$M$5,本职技能!$A$1:$HX$1,0))),0) | F29: 闪避 | J29: =INT(DEX/2) -> 0 | R29: =SUM(J29:Q29) -> 0 | T29: =INT(R29/2) -> 0 | V29: =INT(R29/5) -> 0 | X29: ☐ | Z29: =IFERROR(IF(ISTEXT(IFERROR(VLOOKUP(人物卡!AB29,人物卡!BJ18:BR22,1,FALSE),IFERROR(VLOOKUP(人物卡!AB29,人物卡!BA18:BC22,1,FALSE),0))),"★",INDEX(本职技能!$A$2:$HX$76,MATCH(人物卡!AB29,本职技能!$A$2:$A$75,0),MATCH(人物卡!$M$5,本职技能!$A$1:$HX$1,0))),0) | AB29: 心理学 | AF29: 10 | AN29: =SUM(AF29:AM29) -> 10 | AP29: =INT(AN29/2) -> 5 | AR29: =INT(AN29/5) -> 2 | AT29: =IF(AND(IFERROR(AJ29>0,FALSE),IFERROR(AL29>0,FALSE)),"混点！ ","")&IF(AND(IFERROR(AJ29>0,FALSE),Z29<>"★"),"非本职职业！","") | AU29: 射击技能名称 | BA29: 基础值 | BC29: 备注
A30: =IF(AND(IFERROR(N30>0,FALSE),IFERROR(P30>0,FALSE)),"混点！ ","")&IF(AND(IFERROR(N30>0,FALSE),D30<>"★"),"非本职职业！","") | B30: ☐ | D30: =IFERROR(IF(ISTEXT(IFERROR(VLOOKUP(人物卡!F30,人物卡!BJ18:BR22,1,FALSE),IFERROR(VLOOKUP(人物卡!F30,人物卡!BA18:BC22,1,FALSE),0))),"★",INDEX(本职技能!$A$2:$HX$76,MATCH(人物卡!F30,本职技能!$A$2:$A$75,0),MATCH(人物卡!$M$5,本职技能!$A$1:$HX$1,0))),0) | F30: 汽车驾驶 | J30: 20 | R30: =SUM(J30:Q30) -> 20 | T30: =INT(R30/2) -> 10 | V30: =INT(R30/5) -> 4 | X30: ☐ | Z30: =IFERROR(IF(ISTEXT(IFERROR(VLOOKUP(人物卡!AB30,人物卡!BJ18:BR22,1,FALSE),IFERROR(VLOOKUP(人物卡!AB30,人物卡!BA18:BC22,1,FALSE),0))),"★",INDEX(本职技能!$A$2:$HX$76,MATCH(人物卡!AB30,本职技能!$A$2:$A$75,0),MATCH(人物卡!$M$5,本职技能!$A$1:$HX$1,0))),0) | AB30: 骑术 | AF30: 5 | AN30: =SUM(AF30:AM30) -> 5 | AP30: =INT(AN30/2) -> 2 | AR30: =INT(AN30/5) -> 1 | AT30: =IF(AND(IFERROR(AJ30>0,FALSE),IFERROR(AL30>0,FALSE)),"混点！ ","")&IF(AND(IFERROR(AJ30>0,FALSE),Z30<>"★"),"非本职职业！","")
A31: =IF(AND(IFERROR(N31>0,FALSE),IFERROR(P31>0,FALSE)),"混点！ ","")&IF(AND(IFERROR(N31>0,FALSE),D31<>"★"),"非本职职业！","") | B31: ☐ | D31: =IFERROR(IF(ISTEXT(IFERROR(VLOOKUP(人物卡!F31,人物卡!BJ18:BR22,1,FALSE),IFERROR(VLOOKUP(人物卡!F31,人物卡!BA18:BC22,1,FALSE),0))),"★",INDEX(本职技能!$A$2:$HX$76,MATCH(人物卡!F31,本职技能!$A$2:$A$75,0),MATCH(人物卡!$M$5,本职技能!$A$1:$HX$1,0))),0) | F31: 电气维修 | J31: 10 | R31: =SUM(J31:Q31) -> 10 | T31: =INT(R31/2) -> 5 | V31: =INT(R31/5) -> 2 | X31: ☐ | Z31: =IFERROR(IF(ISTEXT(IFERROR(VLOOKUP(人物卡!AB31,人物卡!BJ18:BR22,1,FALSE),IFERROR(VLOOKUP(人物卡!AB31,人物卡!BA18:BC22,1,FALSE),0))),"★",INDEX(本职技能!$A$2:$HX$76,MATCH(人物卡!AB31,本职技能!$A$2:$A$75,0),MATCH(人物卡!$M$5,本职技能!$A$1:$HX$1,0))),0) | AB31: 科学① | AF31: =IF(ISBLANK(AU34),IF(AD31="数学",10,1),IF(AD31=AU34,BA34,1)) -> 1 | AN31: =SUM(AF31:AM31) -> 1 | AP31: =INT(AN31/2) -> 0 | AR31: =INT(AN31/5) -> 0 | AT31: =IF(AND(IFERROR(AJ31>0,FALSE),IFERROR(AL31>0,FALSE)),"混点！ ","")&IF(AND(IFERROR(AJ31>0,FALSE),Z31<>"★"),"非本职职业！","") | AU31: 驾驶技能名称 | BA31: 基础值
A32: =IF(AND(IFERROR(N32>0,FALSE),IFERROR(P32>0,FALSE)),"混点！ ","")&IF(AND(IFERROR(N32>0,FALSE),D32<>"★"),"非本职职业！","") | B32: ☐ | D32: =IFERROR(IF(ISTEXT(IFERROR(VLOOKUP(人物卡!F32,人物卡!BJ18:BR22,1,FALSE),IFERROR(VLOOKUP(人物卡!F32,人物卡!BA18:BC22,1,FALSE),0))),"★",INDEX(本职技能!$A$2:$HX$76,MATCH(人物卡!F32,本职技能!$A$2:$A$75,0),MATCH(人物卡!$M$5,本职技能!$A$1:$HX$1,0))),0) | F32: 电子学 Ω | J32: 1 | R32: =SUM(J32:Q32) -> 1 | T32: =INT(R32/2) -> 0 | V32: =INT(R32/5) -> 0 | X32: ☐ | Z32: =IFERROR(IF(ISTEXT(IFERROR(VLOOKUP(人物卡!AB32,人物卡!BJ18:BR22,1,FALSE),IFERROR(VLOOKUP(人物卡!AB32,人物卡!BA18:BC22,1,FALSE),0))),"★",INDEX(本职技能!$A$2:$HX$76,MATCH(人物卡!AB32,本职技能!$A$2:$A$75,0),MATCH(人物卡!$M$5,本职技能!$A$1:$HX$1,0))),0) | AB32: 科学② | AF32: =IF(ISBLANK(AU34),IF(AD32="数学",10,1),IF(AD32=AU34,BA34,1)) -> 1 | AN32: =SUM(AF32:AM32) -> 1 | AP32: =INT(AN32/2) -> 0 | AR32: =INT(AN32/5) -> 0 | AT32: =IF(AND(IFERROR(AJ32>0,FALSE),IFERROR(AL32>0,FALSE)),"混点！ ","")&IF(AND(IFERROR(AJ32>0,FALSE),Z32<>"★"),"非本职职业！","")
A33: =IF(AND(IFERROR(N33>0,FALSE),IFERROR(P33>0,FALSE)),"混点！ ","")&IF(AND(IFERROR(N33>0,FALSE),D33<>"★"),"非本职职业！","") | B33: ☐ | D33: =IFERROR(IF(ISTEXT(IFERROR(VLOOKUP(人物卡!F33,人物卡!BJ18:BR22,1,FALSE),IFERROR(VLOOKUP(人物卡!F33,人物卡!BA18:BC22,1,FALSE),0))),"★",INDEX(本职技能!$A$2:$HX$76,MATCH(人物卡!F33,本职技能!$A$2:$A$75,0),MATCH(人物卡!$M$5,本职技能!$A$1:$HX$1,0))),0) | F33: 话术 | J33: 5 | R33: =SUM(J33:Q33) -> 5 | T33: =INT(R33/2) -> 2 | V33: =INT(R33/5) -> 1 | X33: ☐ | Z33: =IFERROR(IF(ISTEXT(IFERROR(VLOOKUP(人物卡!AB33,人物卡!BJ18:BR22,1,FALSE),IFERROR(VLOOKUP(人物卡!AB33,人物卡!BA18:BC22,1,FALSE),0))),"★",INDEX(本职技能!$A$2:$HX$76,MATCH(人物卡!AB33,本职技能!$A$2:$A$75,0),MATCH(人物卡!$M$5,本职技能!$A$1:$HX$1,0))),0) | AB33: 科学③ | AF33: =IF(ISBLANK(AU34),IF(AD33="数学",10,1),IF(AD33=AU34,BA34,1)) -> 1 | AN33: =SUM(AF33:AM33) -> 1 | AP33: =INT(AN33/2) -> 0 | AR33: =INT(AN33/5) -> 0 | AT33: =IF(AND(IFERROR(AJ33>0,FALSE),IFERROR(AL33>0,FALSE)),"混点！ ","")&IF(AND(IFERROR(AJ33>0,FALSE),Z33<>"★"),"非本职职业！","") | AU33: 科学技能名称 | BA33: 基础值
A34: =IF(AND(IFERROR(N34>0,FALSE),IFERROR(P34>0,FALSE)),"混点！ ","")&IF(AND(IFERROR(N34>0,FALSE),D34<>"★"),"非本职职业！","") | B34: ☐ | D34: =IFERROR(IF(ISTEXT(IFERROR(VLOOKUP(人物卡!F34,人物卡!BJ18:BR22,1,FALSE),IFERROR(VLOOKUP(人物卡!F34,人物卡!BA18:BC22,1,FALSE),0))),"★",INDEX(本职技能!$A$2:$HX$76,MATCH(人物卡!F34,本职技能!$A$2:$A$75,0),MATCH(人物卡!$M$5,本职技能!$A$1:$HX$1,0))),0) | F34: 格斗： | H34: 斗殴 | J34: 25 | R34: =SUM(J34:Q34) -> 25 | T34: =INT(R34/2) -> 12 | V34: =INT(R34/5) -> 5 | X34: ☐ | Z34: =IFERROR(IF(ISTEXT(IFERROR(VLOOKUP(人物卡!AB34,人物卡!BJ18:BR22,1,FALSE),IFERROR(VLOOKUP(人物卡!AB34,人物卡!BA18:BC22,1,FALSE),0))),"★",INDEX(本职技能!$A$2:$HX$76,MATCH(人物卡!AB34,本职技能!$A$2:$A$75,0),MATCH(人物卡!$M$5,本职技能!$A$1:$HX$1,0))),0) | AB34: 妙手 | AF34: 10 | AN34: =SUM(AF34:AM34) -> 10 | AP34: =INT(AN34/2) -> 5 | AR34: =INT(AN34/5) -> 2 | AT34: =IF(AND(IFERROR(AJ34>0,FALSE),IFERROR(AL34>0,FALSE)),"混点！ ","")&IF(AND(IFERROR(AJ34>0,FALSE),Z34<>"★"),"非本职职业！","")
A35: =IF(AND(IFERROR(N35>0,FALSE),IFERROR(P35>0,FALSE)),"混点！ ","")&IF(AND(IFERROR(N35>0,FALSE),D35<>"★"),"非本职职业！","") | B35: ☐ | D35: =IFERROR(IF(ISTEXT(IFERROR(VLOOKUP(人物卡!F35,人物卡!BJ18:BR22,1,FALSE),IFERROR(VLOOKUP(人物卡!F35,人物卡!BA18:BC22,1,FALSE),0))),"★",INDEX(本职技能!$A$2:$HX$76,MATCH(人物卡!F35,本职技能!$A$2:$A$75,0),MATCH(人物卡!$M$5,本职技能!$A$1:$HX$1,0))),0) | F35: 格斗① | J35: =附表!C11 -> 0 | R35: =SUM(J35:Q35) -> 0 | T35: =INT(R35/2) -> 0 | V35: =INT(R35/5) -> 0 | X35: ☐ | Z35: =IFERROR(IF(ISTEXT(IFERROR(VLOOKUP(人物卡!AB35,人物卡!BJ18:BR22,1,FALSE),IFERROR(VLOOKUP(人物卡!AB35,人物卡!BA18:BC22,1,FALSE),0))),"★",INDEX(本职技能!$A$2:$HX$76,MATCH(人物卡!AB35,本职技能!$A$2:$A$75,0),MATCH(人物卡!$M$5,本职技能!$A$1:$HX$1,0))),0) | AB35: 侦查 | AF35: 25 | AN35: =SUM(AF35:AM35) -> 25 | AP35: =INT(AN35/2) -> 12 | AR35: =INT(AN35/5) -> 5 | AT35: =IF(AND(IFERROR(AJ35>0,FALSE),IFERROR(AL35>0,FALSE)),"混点！ ","")&IF(AND(IFERROR(AJ35>0,FALSE),Z35<>"★"),"非本职职业！","") | AU35: 自定义年龄补正 | BK35: 自定义货币
A36: =IF(AND(IFERROR(N36>0,FALSE),IFERROR(P36>0,FALSE)),"混点！ ","")&IF(AND(IFERROR(N36>0,FALSE),D36<>"★"),"非本职职业！","") | B36: ☐ | D36: =IFERROR(IF(ISTEXT(IFERROR(VLOOKUP(F36,人物卡!BJ18:BR22,1,FALSE),IFERROR(VLOOKUP(F36,人物卡!BA18:BC22,1,FALSE),0))),"★",INDEX(本职技能!$A$2:$HX$76,MATCH(F36,本职技能!$A$2:$A$75,0),MATCH(人物卡!$M$5,本职技能!$A$1:$HX$1,0))),0) | F36: 格斗② | J36: =附表!C12 -> 0 | R36: =SUM(J36:Q36) -> 0 | T36: =INT(R36/2) -> 0 | V36: =INT(R36/5) -> 0 | X36: ☐ | Z36: =IFERROR(IF(ISTEXT(IFERROR(VLOOKUP(人物卡!AB36,人物卡!BJ18:BR22,1,FALSE),IFERROR(VLOOKUP(人物卡!AB36,人物卡!BA18:BC22,1,FALSE),0))),"★",INDEX(本职技能!$A$2:$HX$76,MATCH(人物卡!AB36,本职技能!$A$2:$A$75,0),MATCH(人物卡!$M$5,本职技能!$A$1:$HX$1,0))),0) | AB36: 潜行 | AF36: 20 | AN36: =SUM(AF36:AM36) -> 20 | AP36: =INT(AN36/2) -> 10 | AR36: =INT(AN36/5) -> 4 | AT36: =IF(AND(IFERROR(AJ36>0,FALSE),IFERROR(AL36>0,FALSE)),"混点！ ","")&IF(AND(IFERROR(AJ36>0,FALSE),Z36<>"★"),"非本职职业！","") | AU36: 年龄补正 | BK36: 货币名称 | BO36: 与美元的汇率
A37: =IF(AND(IFERROR(N37>0,FALSE),IFERROR(P37>0,FALSE)),"混点！ ","")&IF(AND(IFERROR(N37>0,FALSE),D37<>"★"),"非本职职业！","") | B37: ☐ | D37: =IFERROR(IF(ISTEXT(IFERROR(VLOOKUP(F37,人物卡!BJ18:BR22,1,FALSE),IFERROR(VLOOKUP(F37,人物卡!BA18:BC22,1,FALSE),0))),"★",INDEX(本职技能!$A$2:$HX$76,MATCH(F37,本职技能!$A$2:$A$75,0),MATCH(人物卡!$M$5,本职技能!$A$1:$HX$1,0))),0) | F37: 格斗③ | J37: =附表!C13 -> 0 | R37: =SUM(J37:Q37) -> 0 | T37: =INT(R37/2) -> 0 | V37: =INT(R37/5) -> 0 | X37: ☐ | Z37: =IFERROR(IF(ISTEXT(IFERROR(VLOOKUP(人物卡!AB37,人物卡!BJ18:BR22,1,FALSE),IFERROR(VLOOKUP(人物卡!AB37,人物卡!BA18:BC22,1,FALSE),0))),"★",INDEX(本职技能!$A$2:$HX$76,MATCH(人物卡!AB37,本职技能!$A$2:$A$75,0),MATCH(人物卡!$M$5,本职技能!$A$1:$HX$1,0))),0) | AB37: 生存： | AF37: 10 | AN37: =SUM(AF37:AM37) -> 10 | AP37: =INT(AN37/2) -> 5 | AR37: =INT(AN37/5) -> 2 | AT37: =IF(AND(IFERROR(AJ37>0,FALSE),IFERROR(AL37>0,FALSE)),"混点！ ","")&IF(AND(IFERROR(AJ37>0,FALSE),Z37<>"★"),"非本职职业！","") | BK37: =IF('货币汇率'!$K$8="可用",'货币汇率'!$K$3,"请选择可用币种") -> 美元（USD） | BO37: ='货币汇率'!$K$5 -> 1
A38: =IF(AND(IFERROR(N38>0,FALSE),IFERROR(P38>0,FALSE)),"混点！ ","")&IF(AND(IFERROR(N38>0,FALSE),D38<>"★"),"非本职职业！","") | B38: ☐ | D38: =IFERROR(IF(ISTEXT(IFERROR(VLOOKUP(人物卡!F38,人物卡!BJ18:BR22,1,FALSE),IFERROR(VLOOKUP(人物卡!F38,人物卡!BA18:BC22,1,FALSE),0))),"★",INDEX(本职技能!$A$2:$HX$76,MATCH(人物卡!F38,本职技能!$A$2:$A$75,0),MATCH(人物卡!$M$5,本职技能!$A$1:$HX$1,0))),0) | F38: 射击： | H38: 手枪 | J38: 20 | R38: =SUM(J38:Q38) -> 20 | T38: =INT(R38/2) -> 10 | V38: =INT(R38/5) -> 4 | X38: ☐ | Z38: =IFERROR(IF(ISTEXT(IFERROR(VLOOKUP(人物卡!AB38,人物卡!BJ18:BR22,1,FALSE),IFERROR(VLOOKUP(人物卡!AB38,人物卡!BA18:BC22,1,FALSE),0))),"★",INDEX(本职技能!$A$2:$HX$76,MATCH(人物卡!AB38,本职技能!$A$2:$A$75,0),MATCH(人物卡!$M$5,本职技能!$A$1:$HX$1,0))),0) | AB38: 游泳 | AF38: 20 | AN38: =SUM(AF38:AM38) -> 20 | AP38: =INT(AN38/2) -> 10 | AR38: =INT(AN38/5) -> 4 | AT38: =IF(AND(IFERROR(AJ38>0,FALSE),IFERROR(AL38>0,FALSE)),"混点！ ","")&IF(AND(IFERROR(AJ38>0,FALSE),Z38<>"★"),"非本职职业！","") | AU38: 推 荐 关 系 人 | AV38: =IF(M5=0," ",""&LOOKUP(M5,职业列表!A2:A232,职业列表!K2:K232)) -> 列出一些角色在职业工作中可能接触的个人或组织,它们也可以为调查员的个人背景提供灵感。
A39: =IF(AND(IFERROR(N39>0,FALSE),IFERROR(P39>0,FALSE)),"混点！ ","")&IF(AND(IFERROR(N39>0,FALSE),D39<>"★"),"非本职职业！","") | B39: ☐ | D39: =IFERROR(IF(ISTEXT(IFERROR(VLOOKUP(人物卡!F39,人物卡!BJ18:BR22,1,FALSE),IFERROR(VLOOKUP(人物卡!F39,人物卡!BA18:BC22,1,FALSE),0))),"★",INDEX(本职技能!$A$2:$HX$76,MATCH(人物卡!F39,本职技能!$A$2:$A$75,0),MATCH(人物卡!$M$5,本职技能!$A$1:$HX$1,0))),0) | F39: 射击① | J39: =附表!E11 -> 0 | R39: =SUM(J39:Q39) -> 0 | T39: =INT(R39/2) -> 0 | V39: =INT(R39/5) -> 0 | X39: ☐ | Z39: =IFERROR(IF(ISTEXT(IFERROR(VLOOKUP(人物卡!AB39,人物卡!BJ18:BR22,1,FALSE),IFERROR(VLOOKUP(人物卡!AB39,人物卡!BA18:BC22,1,FALSE),0))),"★",INDEX(本职技能!$A$2:$HX$76,MATCH(人物卡!AB39,本职技能!$A$2:$A$75,0),MATCH(人物卡!$M$5,本职技能!$A$1:$HX$1,0))),0) | AB39: 投掷 | AF39: 20 | AN39: =SUM(AF39:AM39) -> 20 | AP39: =INT(AN39/2) -> 10 | AR39: =INT(AN39/5) -> 4 | AT39: =IF(AND(IFERROR(AJ39>0,FALSE),IFERROR(AL39>0,FALSE)),"混点！ ","")&IF(AND(IFERROR(AJ39>0,FALSE),Z39<>"★"),"非本职职业！","")
A40: =IF(AND(IFERROR(N40>0,FALSE),IFERROR(P40>0,FALSE)),"混点！ ","")&IF(AND(IFERROR(N40>0,FALSE),D40<>"★"),"非本职职业！","") | B40: ☐ | D40: =IFERROR(IF(ISTEXT(IFERROR(VLOOKUP(F40,人物卡!BJ18:BR22,1,FALSE),IFERROR(VLOOKUP(F40,人物卡!BA18:BC22,1,FALSE),0))),"★",INDEX(本职技能!$A$2:$HX$76,MATCH(F40,本职技能!$A$2:$A$75,0),MATCH(人物卡!$M$5,本职技能!$A$1:$HX$1,0))),0) | F40: 射击② | J40: =附表!E12 -> 0 | R40: =SUM(J40:Q40) -> 0 | T40: =INT(R40/2) -> 0 | V40: =INT(R40/5) -> 0 | X40: ☐ | Z40: =IFERROR(IF(ISTEXT(IFERROR(VLOOKUP(人物卡!AB40,人物卡!BJ18:BR22,1,FALSE),IFERROR(VLOOKUP(人物卡!AB40,人物卡!BA18:BC22,1,FALSE),0))),"★",INDEX(本职技能!$A$2:$HX$76,MATCH(人物卡!AB40,本职技能!$A$2:$A$75,0),MATCH(人物卡!$M$5,本职技能!$A$1:$HX$1,0))),0) | AB40: 追踪 | AF40: 10 | AN40: =SUM(AF40:AM40) -> 10 | AP40: =INT(AN40/2) -> 5 | AR40: =INT(AN40/5) -> 2 | AT40: =IF(AND(IFERROR(AJ40>0,FALSE),IFERROR(AL40>0,FALSE)),"混点！ ","")&IF(AND(IFERROR(AJ40>0,FALSE),Z40<>"★"),"非本职职业！","")
...

Sheet 简化卡 骰娘导入
B2: =人物卡!E3&"，"&人物卡!M6&"，"&人物卡!E6&"岁"&"，"&人物卡!E5&"，"&人物卡!M4&"，"&"现居："&人物卡!E7&"，"&人物卡!M7&"人" -> ，，岁，，1920s，现居：，人 | N2: 技能 | Z2: 当前时间
B3: STR | C3: =STR -> 0 | D3: =INT(C3/2) -> 0 | E3: DEX | F3: =DEX -> 0 | G3: =INT(F3/2) -> 0 | H3: POW | I3: =POW -> 0 | J3: =INT(I3/2) -> 0 | K3: INT | L3: =INT -> 0 | M3: =INT(L3/2) -> 0 | N3: =IF(Q3=0,"",人物卡!F16) | Q3: =IF(人物卡!R16-人物卡!J16=0,0,人物卡!R16) -> 0 | R3: =INT(Q3/2) -> 0 | S3: =INT(Q3/5) -> 0 | T3: =IF(W3=0,"",人物卡!AB16) | W3: =IF(人物卡!AN16-人物卡!AF16=0,0,人物卡!AN16) -> 0 | X3: =INT(W3/2) -> 0 | Y3: =INT(W3/5) -> 0 | Z3: =人物卡!E8 -> 公元 | AA3: =人物卡!G8 -> 2026 | AC3: =人物卡!J8 -> 1月 | AD3: =人物卡!N8 -> 0：00
D4: =INT(C3/5) -> 0 | G4: =INT(F3/5) -> 0 | J4: =INT(I3/5) -> 0 | M4: =INT(L3/5) -> 0 | N4: =IF(Q4=0,"",人物卡!F17) | Q4: =IF(人物卡!R17-人物卡!J17=0,0,人物卡!R17) -> 0 | R4: =INT(Q4/2) -> 0 | S4: =INT(Q4/5) -> 0 | T4: =IF(W4=0,"",人物卡!AB17) | W4: =IF(人物卡!AN17-人物卡!AF17=0,0,人物卡!AN17) -> 0 | X4: =INT(W4/2) -> 0 | Y4: =INT(W4/5) -> 0 | AC4: =人物卡!L8 -> 1日
B5: CON | C5: =CON -> 0 | D5: =INT(C5/2) -> 0 | E5: APP | F5: =APP -> 0 | G5: =INT(F5/2) -> 0 | H5: EDU | I5: =EDU -> 0 | J5: =INT(I5/2) -> 0 | K5: SIZ | L5: =SIZ -> 0 | M5: =INT(L5/2) -> 0 | N5: =IF(Q5=0,"",人物卡!F18) | Q5: =IF(人物卡!R18-人物卡!J18=0,0,人物卡!R18) -> 0 | R5: =INT(Q5/2) -> 0 | S5: =INT(Q5/5) -> 0 | T5: =IF(W5=0,"",人物卡!AB18) | W5: =IF(人物卡!AN18-人物卡!AF18=0,0,人物卡!AN18) -> 0 | X5: =INT(W5/2) -> 0 | Y5: =INT(W5/5) -> 0 | Z5: 调查员伙伴
D6: =INT(C5/5) -> 0 | G6: =INT(F5/5) -> 0 | J6: =INT(I5/5) -> 0 | M6: =INT(L5/5) -> 0 | N6: =IF(Q6=0,"",人物卡!F19) | Q6: =IF(人物卡!R19-人物卡!J19=0,0,人物卡!R19) -> 0 | R6: =INT(Q6/2) -> 0 | S6: =INT(Q6/5) -> 0 | T6: =IF(W6=0,"",人物卡!AB19) | W6: =IF(人物卡!AN19-人物卡!AF19=0,0,人物卡!AN19) -> 0 | X6: =INT(W6/2) -> 0 | Y6: =INT(W6/5) -> 0 | Z6: 姓名 | AB6: 注释
B7: HP | C7: =人物卡!E10 -> 0 | D7: =人物卡!G10 -> 0 | E7: SAN | F7: =人物卡!N10 -> 0 | G7: =人物卡!P10 -> 0 | H7: MP | I7: =人物卡!W10 -> 0 | J7: =MP -> 0 | K7: Armor | L7: =人物卡!AN10 -> 无 | N7: =IF(Q7=0,0,"技艺：") -> 0 | O7: =IF(N7=0,"",人物卡!H20) | Q7: =IF(人物卡!R20-人物卡!J20=0,0,人物卡!R20) -> 0 | R7: =INT(Q7/2) -> 0 | S7: =INT(Q7/5) -> 0 | T7: =IF(W7=0,"",人物卡!AB20) | W7: =IF(人物卡!AN20-人物卡!AF20=0,0,人物卡!AN20) -> 0 | X7: =INT(W7/2) -> 0 | Y7: =INT(W7/5) -> 0 | Z7: =人物卡!W130 -> 例：丛雨 | AB7: =人物卡!AD130 -> 一起出生入死的医生小姐
N8: =IF(Q8=0,0,"技艺：") -> 0 | O8: =IF(N8=0,"",人物卡!H21) | Q8: =IF(人物卡!R21-人物卡!J21=0,0,人物卡!R21) -> 0 | R8: =INT(Q8/2) -> 0 | S8: =INT(Q8/5) -> 0 | T8: =IF(W8=0,"",人物卡!AB21) | W8: =IF(人物卡!AN21-人物卡!AF21=0,0,人物卡!AN21) -> 0 | X8: =INT(W8/2) -> 0 | Y8: =INT(W8/5) -> 0 | Z8: =人物卡!W131 -> 0 | AB8: =人物卡!AD131 -> 0
B9: DB | C9: =人物卡!AP52 -> 0 | E9: Build | F9: =人物卡!AP55 -> 0 | H9: LUCK | I9: =Luck -> 0 | K9: MOV | L9: =人物卡!AF10 -> 8 | N9: =IF(Q9=0,0,"技艺：") -> 0 | O9: =IF(N9=0,"",人物卡!H22) | Q9: =IF(人物卡!R22-人物卡!J22=0,0,人物卡!R22) -> 0 | R9: =INT(Q9/2) -> 0 | S9: =INT(Q9/5) -> 0 | T9: =IF(W9=0,"",人物卡!AB22) | W9: =IF(人物卡!AN22-人物卡!AF22=0,0,人物卡!AN22) -> 0 | X9: =INT(W9/2) -> 0 | Y9: =INT(W9/5) -> 0 | Z9: =人物卡!W132 -> 0 | AB9: =人物卡!AD132 -> 0
N10: =IF(Q10=0,"",人物卡!F23) | Q10: =IF(人物卡!R23-人物卡!J23=0,0,人物卡!R23) -> 0 | R10: =INT(Q10/2) -> 0 | S10: =INT(Q10/5) -> 0 | T10: =IF(W10=0,"",人物卡!AB23) | W10: =IF(人物卡!AN23-人物卡!AF23=0,0,人物卡!AN23) -> 0 | X10: =INT(W10/2) -> 0 | Y10: =INT(W10/5) -> 0 | Z10: =人物卡!W133 -> 0 | AB10: =人物卡!AD133 -> 0
B11: 武器表 | N11: =IF(Q11=0,"",人物卡!F24) | Q11: =IF(人物卡!R24-人物卡!J24=0,0,人物卡!R24) -> 0 | R11: =INT(Q11/2) -> 0 | S11: =INT(Q11/5) -> 0 | T11: =IF(W11=0,"",人物卡!AB24) | W11: =IF(人物卡!AN24-人物卡!AF24=0,0,人物卡!AN24) -> 0 | X11: =INT(W11/2) -> 0 | Y11: =INT(W11/5) -> 0 | Z11: =人物卡!W134 -> 0 | AB11: =人物卡!AD134 -> 0
B12: =人物卡!B53 -> 无 | C12: =人物卡!G53 -> 肉搏 | D12: =人物卡!M53 -> 斗殴 | E12: =人物卡!Q53 -> 25 | F12: =人物卡!S53 -> 12 | G12: =人物卡!U53 -> 5 | H12: =人物卡!W53 -> 1D3+DB | I12: =人物卡!AA53 -> —— | J12: =人物卡!AC53 -> × | K12: =人物卡!AE53 -> 1 | L12: =人物卡!AG53 -> —— | M12: =人物卡!AJ53 -> —— | N12: =IF(Q12=0,"",人物卡!F25) | Q12: =IF(人物卡!R25-人物卡!J25=0,0,人物卡!R25) -> 0 | R12: =INT(Q12/2) -> 0 | S12: =INT(Q12/5) -> 0 | T12: =IF(W12=0,"",人物卡!AB25) | W12: =IF(人物卡!AN25-人物卡!AF25=0,0,人物卡!AN25) -> 0 | X12: =INT(W12/2) -> 0 | Y12: =INT(W12/5) -> 0 | Z12: =人物卡!W135 -> 0 | AB12: =人物卡!AD135 -> 0
B13: =人物卡!B54 -> 0 | C13: =人物卡!G54 -> 0 | D13: =IF(人物卡!M54="请选择类型","",人物卡!M54) -> ←请选择类型 | E13: =人物卡!Q54 | F13: =人物卡!S54 | G13: =人物卡!U54 | H13: =人物卡!W54 | I13: =人物卡!AA54 | J13: =人物卡!AC54 | K13: =人物卡!AE54 | L13: =人物卡!AG54 | M13: =人物卡!AJ54 | N13: =人物卡!F26 -> 信用评级 | Q13: =人物卡!R26 -> 0 | R13: =IF(Q13=0,32767,INT(Q13/2)) -> 32767 | S13: =IF(Q13=0,32767,INT(Q13/5)) -> 32767 | T13: =IF(W13=0,"",人物卡!AB26) | W13: =IF(人物卡!AN26-人物卡!AF26=0,0,人物卡!AN26) -> 0 | X13: =INT(W13/2) -> 0 | Y13: =INT(W13/5) -> 0 | Z13: =人物卡!W136 -> 0 | AB13: =人物卡!AD136 -> 0
B14: =人物卡!B55 -> 0 | C14: =人物卡!G55 -> 0 | D14: =IF(人物卡!M55="请选择类型","",人物卡!M55) | E14: =人物卡!Q55 | F14: =人物卡!S55 | G14: =人物卡!U55 | H14: =人物卡!W55 | I14: =人物卡!AA55 | J14: =人物卡!AC55 | K14: =人物卡!AE55 | L14: =人物卡!AG55 | M14: =人物卡!AJ55 | N14: =IF(Q14=0,"",人物卡!F27) | Q14: =IF(人物卡!R27-人物卡!J27=0,0,人物卡!R27) -> 0 | R14: =INT(Q14/2) -> 0 | S14: =INT(Q14/5) -> 0 | T14: =IF(W14=0,0,人物卡!AB27) -> 0 | U14: =IF(T14=0,"",人物卡!AD27) | W14: =IF(人物卡!AN27-人物卡!AF27=0,0,人物卡!AN27) -> 0 | X14: =INT(W14/2) -> 0 | Y14: =INT(W14/5) -> 0 | Z14: =人物卡!W137 -> 0 | AB14: =人物卡!AD137 -> 0
B15: =人物卡!B56 -> 0 | C15: =人物卡!G56 -> 0 | D15: =IF(人物卡!M56="请选择类型","",人物卡!M56) | E15: =人物卡!Q56 | F15: =人物卡!S56 | G15: =人物卡!U56 | H15: =人物卡!W56 | I15: =人物卡!AA56 | J15: =人物卡!AC56 | K15: =人物卡!AE56 | L15: =人物卡!AG56 | M15: =人物卡!AJ56 | N15: =IF(Q15=0,"",人物卡!F28) | Q15: =IF(人物卡!R28-人物卡!J28=0,0,人物卡!R28) -> 0 | R15: =INT(Q15/2) -> 0 | S15: =INT(Q15/5) -> 0 | T15: =IF(W15=0,"",人物卡!AB28) | W15: =IF(人物卡!AN28-人物卡!AF28=0,0,人物卡!AN28) -> 0 | X15: =INT(W15/2) -> 0 | Y15: =INT(W15/5) -> 0 | Z15: =人物卡!W138 -> 0 | AB15: =人物卡!AD138 -> 0
B16: =人物卡!B57 -> 0 | C16: =人物卡!G57 -> 0 | D16: =IF(人物卡!M57="请选择类型","",人物卡!M57) -> 0 | E16: =人物卡!Q57 -> 0 | F16: =人物卡!S57 -> 0 | G16: =人物卡!U57 -> 0 | H16: =人物卡!W57 -> 0 | I16: =人物卡!AA57 -> 0 | J16: =人物卡!AC57 -> 0 | K16: =人物卡!AE57 -> 0 | L16: =人物卡!AG57 -> 0 | M16: =人物卡!AJ57 -> 0 | N16: =人物卡!F29 -> 闪避 | Q16: =人物卡!R29 -> 0 | R16: =IF(Q16=0,32767,INT(Q16/2)) -> 32767 | S16: =IF(Q16=0,32767,INT(Q16/5)) -> 32767 | T16: =IF(W16=0,"",人物卡!AB29) | W16: =IF(人物卡!AN29-人物卡!AF29=0,0,人物卡!AN29) -> 0 | X16: =INT(W16/2) -> 0 | Y16: =INT(W16/5) -> 0 | Z16: =人物卡!W139 -> 0 | AB16: =人物卡!AD139 -> 0
B17: 资产 | N17: =IF(Q17=0,"",人物卡!F30) | Q17: =IF(人物卡!R30-人物卡!J30=0,0,人物卡!R30) -> 0 | R17: =INT(Q17/2) -> 0 | S17: =INT(Q17/5) -> 0 | T17: =IF(W17=0,"",人物卡!AB30) | W17: =IF(人物卡!AN30-人物卡!AF30=0,0,人物卡!AN30) -> 0 | X17: =INT(W17/2) -> 0 | Y17: =INT(W17/5) -> 0 | Z17: =人物卡!W140 -> 0 | AB17: =人物卡!AD140 -> 0
B18: 信用评级 | E18: 生活水平 | G18: 消费水平 | I18: 其他资产 | K18: 当前现金($) | M18: 单位 | N18: =IF(Q18=0,"",人物卡!F31) | Q18: =IF(人物卡!R31-人物卡!J31=0,0,人物卡!R31) -> 0 | R18: =INT(Q18/2) -> 0 | S18: =INT(Q18/5) -> 0 | T18: =IF(W18=0,0,"科学：") -> 0 | U18: =IF(T18=0,"",人物卡!AD31) | W18: =IF(人物卡!AN31-人物卡!AF31=0,0,人物卡!AN31) -> 0 | X18: =INT(W18/2) -> 0 | Y18: =INT(W18/5) -> 0
B19: =人物卡!B62 -> 0%/0%/0% | E19: =人物卡!F62 -> 身无分文 | G19: =人物卡!I62 -> 0.5 | I19: =人物卡!L62 -> 0 | K19: =人物卡!O62 -> 0.5 | M19: =人物卡!S62 -> 美元（USD） | N19: =IF(Q19=0,"",人物卡!F32) | Q19: =IF(人物卡!R32-人物卡!J32=0,0,人物卡!R32) -> 0 | R19: =INT(Q19/2) -> 0 | S19: =INT(Q19/5) -> 0 | T19: =IF(W19=0,0,"科学：") -> 0 | U19: =IF(T19=0,"",人物卡!AD32) | W19: =IF(人物卡!AN32-人物卡!AF32=0,0,人物卡!AN32) -> 0 | X19: =INT(W19/2) -> 0 | Y19: =INT(W19/5) -> 0
B20: =人物卡!L63 -> 请在这里详述你的资产 | N20: =IF(Q20=0,"",人物卡!F33) | Q20: =IF(人物卡!R33-人物卡!J33=0,0,人物卡!R33) -> 0 | R20: =INT(Q20/2) -> 0 | S20: =INT(Q20/5) -> 0 | T20: =IF(W20=0,0,"科学：") -> 0 | U20: =IF(T20=0,"",人物卡!AD33) | W20: =IF(人物卡!AN33-人物卡!AF33=0,0,人物卡!AN33) -> 0 | X20: =INT(W20/2) -> 0 | Y20: =INT(W20/5) -> 0
B21: 随身物品 | N21: =IF(Q21=0,0,"格斗：") -> 0 | O21: =IF(N21=0,"",人物卡!H34) | Q21: =IF(人物卡!R34-人物卡!J34=0,0,人物卡!R34) -> 0 | R21: =INT(Q21/2) -> 0 | S21: =INT(Q21/5) -> 0 | T21: =IF(W21=0,"",人物卡!AB34) | W21: =IF(人物卡!AN34-人物卡!AF34=0,0,人物卡!AN34) -> 0 | X21: =INT(W21/2) -> 0 | Y21: =INT(W21/5) -> 0 | Z21: 神话相关
B22: =人物卡!F79 -> 0 | E22: =人物卡!F80 -> 0 | H22: =人物卡!F81 -> 0 | K22: =人物卡!F82 -> 0 | N22: =IF(Q22=0,0,"格斗：") -> 0 | O22: =IF(N22=0,"",人物卡!H35) | Q22: =IF(人物卡!R35-人物卡!J35=0,0,人物卡!R35) -> 0 | R22: =INT(Q22/2) -> 0 | S22: =INT(Q22/5) -> 0 | T22: =IF(W22=0,"",人物卡!AB35) | W22: =IF(人物卡!AN35-人物卡!AF35=0,0,人物卡!AN35) -> 0 | X22: =INT(W22/2) -> 0 | Y22: =INT(W22/5) -> 0 | Z22: 遇到了 | AD22: 累计消耗
B23: =人物卡!F83 -> 0 | E23: =人物卡!F84 -> 0 | H23: =人物卡!F85 -> 0 | K23: =人物卡!F90 -> 0 | N23: =IF(Q23=0,0,"格斗：") -> 0 | O23: =IF(N23=0,"",人物卡!H36) | Q23: =IF(人物卡!R36-人物卡!J36=0,0,人物卡!R36) -> 0 | R23: =INT(Q23/2) -> 0 | S23: =INT(Q23/5) -> 0 | T23: =IF(W23=0,"",人物卡!AB36) | W23: =IF(人物卡!AN36-人物卡!AF36=0,0,人物卡!AN36) -> 0 | X23: =INT(W23/2) -> 0 | Y23: =INT(W23/5) -> 0 | Z23: =人物卡!W98 -> 例：米-戈 | AD23: =人物卡!AR98 -> 6
B24: =人物卡!F91 -> 0 | E24: =人物卡!F92 -> 0 | H24: =人物卡!N79 -> 0 | K24: =人物卡!N80 -> 0 | N24: =IF(Q24=0,0,"格斗：") -> 0 | O24: =IF(N24=0,"",人物卡!H37) | Q24: =IF(人物卡!R37-人物卡!J37=0,0,人物卡!R37) -> 0 | R24: =INT(Q24/2) -> 0 | S24: =INT(Q24/5) -> 0 | T24: =IF(W24=0,0,人物卡!AB37) -> 0 | U24: =IF(T24=0,"",人物卡!AD37) | W24: =IF(人物卡!AN37-人物卡!AF37=0,0,人物卡!AN37) -> 0 | X24: =INT(W24/2) -> 0 | Y24: =INT(W24/5) -> 0 | Z24: =人物卡!W99 -> 例：修格斯 | AD24: =人物卡!AR99 -> 5
B25: =人物卡!N81 -> 0 | E25: =人物卡!N82 -> 0 | H25: =人物卡!N83 -> 0 | K25: =人物卡!N84 -> 0 | N25: =IF(Q25=0,0,"射击：") -> 0 | O25: =IF(N25=0,"",人物卡!H38) | Q25: =IF(人物卡!R38-人物卡!J38=0,0,人物卡!R38) -> 0 | R25: =INT(Q25/2) -> 0 | S25: =INT(Q25/5) -> 0 | T25: =IF(W25=0,"",人物卡!AB38) | W25: =IF(人物卡!AN38-人物卡!AF38=0,0,人物卡!AN38) -> 0 | X25: =INT(W25/2) -> 0 | Y25: =INT(W25/5) -> 0 | Z25: =人物卡!W100 -> 0 | AD25: =人物卡!AR100 -> 0
B26: =人物卡!N85 -> 0 | E26: =人物卡!N90 -> 0 | H26: =人物卡!N91 -> 0 | K26: =人物卡!N92 -> 0 | N26: =IF(Q26=0,0,"射击：") -> 0 | O26: =IF(N26=0,"",人物卡!H39) | Q26: =IF(人物卡!R39-人物卡!J39=0,0,人物卡!R39) -> 0 | R26: =INT(Q26/2) -> 0 | S26: =INT(Q26/5) -> 0 | T26: =IF(W26=0,"",人物卡!AB39) | W26: =IF(人物卡!AN39-人物卡!AF39=0,0,人物卡!AN39) -> 0 | X26: =INT(W26/2) -> 0 | Y26: =INT(W26/5) -> 0 | Z26: =人物卡!W101 -> 0 | AD26: =人物卡!AR101 -> 0
B27: 背景故事 | N27: =IF(Q27=0,0,"射击：") -> 0 | O27: =IF(N27=0,"",人物卡!H40) | Q27: =IF(人物卡!R40-人物卡!J40=0,0,人物卡!R40) -> 0 | R27: =INT(Q27/2) -> 0 | S27: =INT(Q27/5) -> 0 | T27: =IF(W27=0,"",人物卡!AB40) | W27: =IF(人物卡!AN40-人物卡!AF40=0,0,人物卡!AN40) -> 0 | X27: =INT(W27/2) -> 0 | Y27: =INT(W27/5) -> 0 | Z27: =人物卡!W102 -> 0 | AD27: =人物卡!AR102 -> 0
B28: 描述 | C28: =人物卡!AA61 -> 0 | G28: 关键 | H28: =人物卡!W77 -> 请务必在此填写背景故事！ 使用Alt+Enter换行 | N28: =IF(Q28=0,0,"射击：") -> 0 | O28: =IF(N28=0,"",人物卡!H41) | Q28: =IF(人物卡!R41-人物卡!J41=0,0,人物卡!R41) -> 0 | R28: =INT(Q28/2) -> 0 | S28: =INT(Q28/5) -> 0 | T28: =IF(W28=0,"",人物卡!AB41) | W28: =IF(人物卡!AN41-人物卡!AF41=0,0,人物卡!AN41) -> 0 | X28: =INT(W28/2) -> 0 | Y28: =INT(W28/5) -> 0 | Z28: =人物卡!W103 -> 0 | AD28: =人物卡!AR103 -> 0
B29: 信仰 | C29: =人物卡!AA63 -> 0 | G29: =人物卡!AR63 -> ☐ | N29: =IF(Q29=0,"",人物卡!F42) | Q29: =IF(人物卡!R42-人物卡!J42=0,0,人物卡!R42) -> 0 | R29: =INT(Q29/2) -> 0 | S29: =INT(Q29/5) -> 0 | T29: =IF(W29=0,"",人物卡!AB42) | W29: =IF(人物卡!AN42-人物卡!AF42=0,0,人物卡!AN42) -> 0 | X29: =INT(W29/2) -> 0 | Y29: =INT(W29/5) -> 0 | Z29: =人物卡!W104 -> 0 | AD29: =人物卡!AR104 -> 0
B30: 重要人 | C30: =人物卡!AA65 -> 0 | G30: =人物卡!AR65 -> ☐ | N30: =IF(Q30=0,"",人物卡!F43) | Q30: =IF(人物卡!R43-人物卡!J43=0,0,人物卡!R43) -> 0 | R30: =INT(Q30/2) -> 0 | S30: =INT(Q30/5) -> 0 | T30: =IF(W30=0,"",人物卡!AB43) | W30: =IF(人物卡!AN43-人物卡!AF43=0,0,人物卡!AN43) -> 0 | X30: =INT(W30/2) -> 0 | Y30: =INT(W30/5) -> 0 | Z30: =人物卡!W105 -> 0 | AD30: =人物卡!AR105 -> 0
B31: 重要地 | C31: =人物卡!AA67 -> 0 | G31: =人物卡!AR67 -> ☐ | N31: =IF(Q31=0,"",人物卡!F44) | Q31: =IF(人物卡!R44-人物卡!J44=0,0,人物卡!R44) -> 0 | R31: =INT(Q31/2) -> 0 | S31: =INT(Q31/5) -> 0 | T31: =IF(W31=0,"",人物卡!AB44) | W31: =IF(人物卡!AN44-人物卡!AF44=0,0,人物卡!AN44) -> 0 | X31: =INT(W31/2) -> 0 | Y31: =INT(W31/5) -> 0 | Z31: =人物卡!W106 -> 0 | AD31: =人物卡!AR106 -> 0
B32: 宝物 | C32: =人物卡!AA69 -> 0 | G32: =人物卡!AR69 -> ☐ | N32: =IF(Q32=0,"",人物卡!F45) | Q32: =IF(人物卡!R45-人物卡!J45=0,0,人物卡!R45) -> 0 | R32: =INT(Q32/2) -> 0 | S32: =INT(Q32/5) -> 0 | T32: =IF(W32=0,"",人物卡!AB45) | W32: =IF(人物卡!AN45-人物卡!AF45=0,0,人物卡!AN45) -> 0 | X32: =INT(W32/2) -> 0 | Y32: =INT(W32/5) -> 0 | Z32: =人物卡!W107 -> 0 | AD32: =人物卡!AR107 -> 0
B33: 特质 | C33: =人物卡!AA71 -> 0 | G33: =人物卡!AR71 -> ☐ | N33: =IF(Q33=0,0,"外语：") -> 0 | O33: =IF(N33=0,"",人物卡!H46) | Q33: =IF(人物卡!R46-人物卡!J46=0,0,人物卡!R46) -> 0 | R33: =INT(Q33/2) -> 0 | S33: =INT(Q33/5) -> 0 | T33: =IF(W33=0,"",人物卡!AB46) | W33: =IF(人物卡!AN46-人物卡!AF46=0,0,人物卡!AN46) -> 0 | X33: =INT(W33/2) -> 0 | Y33: =INT(W33/5) -> 0 | Z33: =人物卡!W108 -> 0 | AD33: =人物卡!AR108 -> 0
B34: 伤疤 | C34: =人物卡!AA73 -> 0 | G34: =人物卡!AR73 -> ☐ | N34: =IF(Q34=0,0,"外语：") -> 0 | O34: =IF(N34=0,"",人物卡!H47) | Q34: =IF(人物卡!R47-人物卡!J47=0,0,人物卡!R47) -> 0 | R34: =INT(Q34/2) -> 0 | S34: =INT(Q34/5) -> 0 | T34: =IF(W34=0,"",人物卡!AB47) | W34: =IF(人物卡!AN47-人物卡!AF47=0,0,人物卡!AN47) -> 0 | X34: =INT(W34/2) -> 0 | Y34: =INT(W34/5) -> 0
B35: 恐惧 | C35: =人物卡!AA75 -> 0 | G35: =人物卡!AR75 -> ☐ | N35: =IF(Q35=0,0,"外语：") -> 0 | O35: =IF(N35=0,"",人物卡!H48) | Q35: =IF(人物卡!R48-人物卡!J48=0,0,人物卡!R48) -> 0 | R35: =INT(Q35/2) -> 0 | S35: =INT(Q35/5) -> 0 | T35: =IF(W35=0,"",人物卡!AB48) | W35: =IF(人物卡!AN48-人物卡!AF48=0,0,人物卡!AN48) -> 0 | X35: =INT(W35/2) -> 0 | Y35: =INT(W35/5) -> 0
N36: 母语： | O36: =人物卡!H49 -> 0 | Q36: =人物卡!R49 -> 0 | R36: =IF(Q36=0,32767,INT(Q36/2)) -> 32767 | S36: =IF(Q36=0,32767,INT(Q36/5)) -> 32767 | T36: =IF(W36=0,"",人物卡!AB49) | W36: =IF(人物卡!AN49-人物卡!AF49=0,0,人物卡!AN49) -> 0 | X36: =INT(W36/2) -> 0 | Y36: =INT(W36/5) -> 0 | AF36: 电脑请先将快捷输入复制到下面的框中，再复制框中内容到QQ
B37: 下面就是快捷输入了，手机一般轻点两下就可以复制啦，电脑请先复制到右边的本文框 | P37: 不知道用什么导入看导入框右侧的说明～ | AF37: 电脑本文输入框
B38: 全技能导入，无简化，基本适合全部骰娘
B39: 请“复制”下格，就可以导出文本，放进QQ发送给骰子娘啦 | Z39: → | AA39: 绝大部分骰娘，包括OlivaDice、Dice!、MDice、塔骰，海豹等。 | AF39: 如果不能使用，请复制到txt文档，然后再复制到QQ
B40: =附表!S24 -> .st 力量0str0敏捷0dex0意志0pow0体质0con0外貌0app0教育0edu0体型0siz0智力0灵感0int0san0san值0理智0理智值0幸运0运气0mp0魔法0hp0体力0会计5人类学1估价5考古学1取悦15魅惑15攀爬20计算机5计算机使用5电脑5信用0信誉0信用评级0克苏鲁0克苏鲁神话0cm0乔装5闪避0汽车20驾驶20汽车驾驶20电气维修10电子学1话术5斗殴25手枪20急救30历史5恐吓15跳跃20母语0法律5图书馆20图书馆使用20聆听20开锁1撬锁1锁匠1机械维修10医学1博物学10自然学10领航10导航10神秘学5重型操作1重型机械1操作重型机械1重型1说服10精神分析1心理学10骑术5妙手10侦查25潜行20生存10游泳20投掷20追踪10动物驯养5潜水1爆破1读唇1催眠1炮术1
B44: 带有调查员姓名的全导入
...

Sheet 职业列表
A1: 序号 | B1: 职业 | D1: 信用评级 | E1: 职业属性 | F1: 技能点 | G1: 本职技能 | K1: 推荐关系人 | M1: 职业介绍
A2: 0 | B2: 选择职业序号为0，则清除职业模板提示和点数计算器。 | H2: 右侧下拉框选择自定义职业技能与属性 （excel2007及以下不适用） | I2: 自定义职业本职技能
A3: 1 | B3: =IF(C3="","自定义职业",C3) -> 自定义职业 | E3: =附表!AA9 -> 教育×4 | F3: =SUM(附表!AF10:AF12) -> 0 | G3: =IF(I3<>"",I3&"，"&I4&"，"&I5&"，"&I6&"，"&I7&"，"&I8&"，"&I9&"，"&I10,"不多于8个本职技能。在右侧职业属性中输入第二职业属性的数值（留空则视为EDU）并自行设置起始信誉。使用自定义职业前，请先咨询你的守秘人。") -> 不多于8个本职技能。在右侧职业属性中输入第二职业属性的数值（留空则视为EDU）并自行设置起始信誉。使用自定义职业前，请先咨询你的守秘人。 | K3: 列出一些角色在职业工作中可能接触的个人或组织,它们也可以为调查员的个人背景提供灵感。 | M3: 不多于7个本职技能。 在职业属性中输入第二职业属性的名字（如外貌、意志、教育、敏捷、力量、体质、体型，留空则视为EDU）并自行设置起始信誉。使用自定义职业前，请先咨询你的KP
A4: 2 | B4: 会计师 | D4: 30-70 | E4: 教育×4 | F4: =EDU*4 -> 0 | G4: 会计，法律，图书馆，聆听，说服，侦查，任意其他两项个人或时代特长。 | K4: 生意伙伴，法律界，金融业界(银行，其他会计师)。 | M4: 会计师可能在企业工作或作为自由会计师，为个体经营者和企业客户担任顾问。 他们是优秀的研究者，既勤奋又关注细节，能够通过仔细分析个人和企业事务历史记录、财务报表和其他记录支持其他调查员。
A5: 3 | B5: 杂技演员 | D5: 9-20 | E5: 教育×2＋敏捷×2 | F5: =EDU*2+DEX*2 -> 0 | G5: 攀爬，闪避，跳跃，投掷，侦查，游泳，任意两项其他个人或时代特长。 | K5: 业余运动员圈，体育专栏作家，马戏团，嘉年华管理者。 | M5: 杂技演员可能是参加各级比赛(甚至奥运会)的业余运动员，也可能是专业的演员，在马戏团、嘉年华、歌舞团之类的地方作为娱乐业从业者工作。
A6: 4 | B6: 演员-戏剧演员 | D6: 9-40 | E6: 教育×2＋外貌×2 | F6: =EDU*2+APP*2 -> 0 | G6: 技艺（表演），乔装，格斗，历史，两项社交技能（取悦、话术、恐吓、说服），心理学，任意一项其他个人或时代特长。 | K6: 戏剧产业，报刊艺术批评家，演员公会。 | M6: 一般指舞台剧演员和电影演员。许多演员有相当深厚的文化素养，认为自己才是“正统”的，倾向于轻视电影业的商业活动。直到20 世纪后期电影业的地位提高，电影演员的薪酬增加，这种情况才发生改变。 电影业和电影明星一直是世界人民关注的焦点。许多明星一夜成名，在媒体的聚光灯下过着光鲜亮丽的生活。 在1920 年代，虽然全国都有大型剧院，美国的戏剧中心仍然是纽约城。英国的情况与之相近，戏剧的中心在伦敦，其他的剧团则在各郡作巡回演出。巡回剧团乘火车旅行，演出内容既包括新编剧目，也包括莎士比亚和其他人的传统剧目。有些剧团也会花时间去国外采风，通常是去加拿大、夏威夷、澳大利亚和欧洲大陆。 20 年代后期出现了有声电影，不少默片时代的明星难以适应有声电影的冲击，挥舞手臂的夸张扮演从此让位给了细致入微的角色特写。这段时间前期的明星包括约翰·加菲尔德和弗兰西斯·布什曼，后期则是贾莱·库珀和琼·克劳馥。
A7: 5 | B7: 演员-电影演员 | D7: 20-90 | E7: 教育×2＋外貌×2 | F7: =EDU*2+APP*2 -> 0 | G7: 技艺（表演），乔装，汽车驾驶，两项社交技能（取悦、话术、恐吓、说服），心理学，任意两项其他个人或时代特长（如骑乘或格斗）。 | K7: 电影工作室，媒体评论员，作家。 | M7: 一般指舞台剧演员和电影演员。许多演员有相当深厚的文化素养，认为自己才是“正统”的，倾向于轻视电影业的商业活动。直到20 世纪后期电影业的地位提高，电影演员的薪酬增加，这种情况才发生改变。 电影业和电影明星一直是世界人民关注的焦点。许多明星一夜成名，在媒体的聚光灯下过着光鲜亮丽的生活。 在1920 年代，虽然全国都有大型剧院，美国的戏剧中心仍然是纽约城。英国的情况与之相近，戏剧的中心在伦敦，其他的剧团则在各郡作巡回演出。巡回剧团乘火车旅行，演出内容既包括新编剧目，也包括莎士比亚和其他人的传统剧目。有些剧团也会花时间去国外采风，通常是去加拿大、夏威夷、澳大利亚和欧洲大陆。 20 年代后期出现了有声电影，不少默片时代的明星难以适应有声电影的冲击，挥舞手臂的夸张扮演从此让位给了细致入微的角色特写。这段时间前期的明星包括约翰·加菲尔德和弗兰西斯·布什曼，后期则是贾莱·库珀和琼·克劳馥。
A8: 6 | B8: 事务所侦探、保安 | D8: 20-45 | E8: 教育×2＋力量或敏捷×2 | F8: =EDU*2+MAX(STR*2,DEX*2) -> 0 | G8: 一项社交技能（取悦、话术、恐吓、说服），格斗（斗殴），射击，法律，图书馆，心理学，潜行，追踪。 | K8: 本地执法机构，客户。 | M8: 世界上有许多著名的侦探机构，其中最著名的是平克顿和伯恩斯调查局(后来合并成一家公司)。这样的公司一般有两类工作人员：安保人员和调查人员。 企业或个人雇用安保人员来保护自己的资产和人员免受盗贼、刺客和绑匪的威胁。这些安保人员角色使用巡警的职业模板。调查人员则是便衣侦探，负责为公司客户解决各种异常事件、阻止谋杀事件、寻找失踪的人员等等。
A9: 7 | B9: 精神病医生（古典） | D9: 10-60 | E9: 教育×4 | F9: =EDU*4 -> 0 | G9: 法律，聆听，医学，外语，精神分析，心理学，科学（生物学，化学）。 | K9: 其他精神疾病研究者，医生，有时还有执法机构的侦探。 | M9: 在1920 年代，“精神病医生”这个词专用来称呼治疗精神失常的医生(也就是早期的精神科医生)。精神分析在当时的美国鲜为人知，而且它的基本内容都是性生活和如厕训练之类令大众不齿的东西。精神病学，一种正规的从行为主义发展来的医学理论则要普及得多。精神病医生、精神科医生和神经科医生还经常爆发激烈的论战。
A10: 8 | B10: 动物训练师 | D10: 10-40 | E10: 教育×2＋外貌或意志×2 | F10: =EDU*2+MAX(APP*2,POW*2) -> 0 | G10: 跳跃，聆听，自然，心理学，科学（动物学），潜行，追踪，任意一项其他个人或时代特长。 | K10: 动物园，马戏团，赞助人，演员。 | M10: 动物训练师可能在电影工作室、巡回马戏团、马厩工作或自由工作。不管是训练导盲犬、狮子钻火圈，他们工作时基本要独自一人长时间近距离地照看这些动物。动物训练师可以像对人一样对动物使用「心理学」技能。
A11: 9 | B11: 文物学家（原作向） | D11: 30-70 | E11: 教育×4 | F11: =EDU*4 -> 0 | G11: 估价，技艺（任一），历史，图书馆，外语，一项社交技能（取悦、话术、恐吓、说服），侦查，任意一项其他个人或时代特长。 | I11: 任意特长数 | K11: 书商，古董收藏者，历史研究学会。 | M11: 文物学家也许是调查员可以从事的最具有洛夫克拉夫特风格的职业：那些历久弥新的的卓越作品、湮没在古代传说中的神奇力量，总能使他们乐在其中。独立的收入使文物学家能够研究古旧晦涩的文物，或者根据自己的兴趣爱好集中探寻特别的种类。他们通常有着欣赏的眼光、敏锐的头脑，和讽刺无知、自大、贪婪者的愚蠢时尖酸刻薄的幽默。
A12: 10 | B12: 古董商 | D12: 30-50 | E12: 教育×4 | F12: =EDU*4 -> 0 | G12: 会计，估价，汽车驾驶，两项社交技能（取悦、话术、恐吓、说服），历史，图书馆，导航。 | K12: 本地的历史学家，其他古董商，可能还包括赝造师。 | M12: 古董商通常自己开店，从自己所在的地方转卖物品，或继续扩展业务范围，通过倒卖物品到城市商店赚取利润。
A13: 11 | B13: 考古学家（原作向） | D13: 10-40 | E13: 教育×4 | F13: =EDU*4 -> 0 | G13: 估价，考古，历史，外语，图书馆，侦查，机械维修，导航或科学（任一：如化学、物理、地理等）。 | H13: 自定义职业属性 | K13: 赞助人，博物馆，大学。 | M13: 考古学家研究探索历史的痕迹。主要来说，是对人类历史相关的物质数据进行各种鉴识、检查、分析。这项工作包含辛苦细致的研究，更不必提情愿亲自下斗铲土的决心。 在1920 年代，成功的考古学家会被当成著名冒险家与探险家，名利双收。有人运用科学方法考古，不过更多的人对付老祖宗的秘密时喜好暴力破解的办法，甚至祭出炸药，这种碉堡了的办法现代人可是很难看得惯的。
A14: 12 | B14: 建筑师 | D14: 30-70 | E14: 教育×4 | F14: =EDU*4 -> 0 | G14: 会计，技艺（技术制图），法律，母语，计算机或图书馆，说服，心理学，科学（数学）。 | H14: 属性名称 | I14: 是否使用 | J14: 使用倍数 | K14: 本地建设和城市规划部门，建筑公司。 | M14: 建筑师掌握设计和营造建筑的知识，不论是个人房屋的改造还是造价数百万美元的地标工程。建筑师与项目经理紧密合作，负责监督施工全程。建筑师必须了解当地的规划法律，健康和安全法规，和基础的公众安全原则。他们既可以在大公司工作，也可以自由工作，这在很大程度上取决于信誉。 在1920 年代，许多人尝试在自家或小办公室单干。不过他们苦心创造的宏伟设计很少能卖得出去。 建筑师也可能专擅某一学科，比如军事建筑或景观工程等。
A15: 13 | B15: 艺术家 | D15: 9-50 | E15: 教育×2＋敏捷或意志×2 | F15: =EDU*2+MAX(DEX*2,POW*2) -> 0 | G15: 技艺（任一），历史或自然，一项社交技能（取悦、话术、恐吓、说服），外语，心理学，侦查，任意两项其他个人或时代特长。 | H15: 力量 | I15: × | J15: =IF(I15="√",2,0) -> 0 | K15: 美术馆，美术批评家，富有的赞助人，广告业者。 | M15: 艺术家在这里可以是画家，雕塑家等等。他们有时沈浸于自己虚幻的想象当中，有时又沐浴在激发热情和理解的灵感之下。不论是否天资优秀，艺术家的内心必须足够强大，这样才能战胜生涯起步时的障碍和挑剔的眼光，并且在自己小有名气以后继续努力。有些艺术家对物质生活是否丰富并不在乎，而有些则有着强烈的创业倾向。
A16: 14 | B16: 精神病院看护 | D16: 8-20 | E16: 教育×2＋力量或敏捷×2 | F16: =EDU*2+MAX(STR*2,DEX*2) -> 0 | G16: 闪避，格斗（斗殴），急救，两项社交技能（取悦、话术、恐吓、说服），聆听，心理学，潜行。 | H16: 敏捷 | I16: × | J16: =IF(I16="√",2,0) -> 0 | K16: 医护人员，患者和患者家属。允许接触医疗记录、药品或其他医疗用品。 | M16: 尽管少数富有的人会选择私人疗养院，大多精神病患者最终会被安置到州县设置的定点医院。这些地方除了医生护士以外，还会有一支看护队伍。选聘看护的时候，力量和体格往往比医学知识更被看重。
A17: 15 | B17: 运动员 | D17: 9-70 | E17: 教育×2＋力量或敏捷×2 | F17: =EDU*2+MAX(STR*2,DEX*2) -> 0 | G17: 攀爬，跳跃，格斗（斗殴），骑乘，一项社交技能（取悦、话术、恐吓、说服），游泳，投掷，任意一项其他个人或时代特长。 | H17: 体质 | I17: × | J17: =IF(I17="√",2,0) -> 0 | K17: 体育界，体育专栏作家，其他明星。 | M17: 运动员可能效力于职业的棒球、足球、板球或者篮球队伍。这支队伍也许是大联盟队伍，有着稳定工资，参加的比赛万人瞩目；或者是众多小联盟队伍之一，尤其是在1920 年代的棒球界。这些队伍往往寄于大联盟队伍篱下，各方面都受其管理，工资更是刚够运动员糊口又不至于让他们跳槽的水平。 成功的运动员在自己的专业领域会拥有相当的声誉——现今尤其如此，在世界各地都能看到体育明星和电影明星并肩站在红地毯上的场景。
A18: 16 | B18: 作家（原作向） | D18: 9-30 | E18: 教育×4 | F18: =EDU*4 -> 0 | G18: 技艺（文学），历史，图书馆，自然或神秘学，外语，母语，心理学，任意一项其他个人或时代特长。 | H18: 体型 | I18: × | J18: =IF(I18="√",2,0) -> 0 | K18: 出版社，文学评论家，历史学家等。 | M18: 作家不同于记者，他们用文字定义和探讨人们的社会生活，尤其是人们的情感变化。他们的劳动通常孤立而又自我中心：虽然以前写作是个能稳拿工资的行当，但如今只靠写作发大财的人屈指可数。 作家的工作习惯相差极大。通常作家们会花费数月乃至数年的时间调查取材，为新书的创作做准备；然后闭门谢客，投入紧张的创作。
A19: 17 | B19: 酒保 | D19: 8-25 | E19: 教育×2＋外貌×2 | F19: =EDU*2+APP*2 -> 0 | G19: 会计，两项社交技能（取悦、话术、恐吓、说服），格斗（斗殴），聆听，心理学，侦查，任意一项其他个人或时代特长。 | H19: 外貌 | I19: × | J19: =IF(I19="√",2,0) -> 0 | K19: 常客，可能有犯罪组织。 | M19: 酒保虽然不一定是酒吧的掌柜，却一定是所有客人的朋友。对客人们的好声气，一部分来说是出于他们的职业或者业务，而更多的来说则是达到目的的一种手段。 1920 年代，由于禁酒令的存在，酒保变成了非法的职业；但是遍地开花的黑酒吧又不能没有酒保，结果就是酒保仍然不愁找不到活干。
A20: 18 | B20: 猎人 | D20: 20-50 | E20: 教育×2＋力量或敏捷×2 | F20: =EDU*2+MAX(STR*2,DEX*2) -> 0 | G20: 射击，聆听或侦查，自然，导航，外语或生存（任一），科学（生物学或植物学），潜行，追踪。 | H20: 智力 | I20: × | J20: =IF(I20="√",2,0) -> 0 | K20: 外国政府官员，狩猎监管人员，前客户(大多很有钱)，黑市商人与黑社会，动物园主。 | M20: 猎人是优秀的追踪者和狩猎者，通常靠为富裕的客户捕猎为生。绝大多数猎人会对地球上某一个部分的情况烂熟于心，比如加拿大森林、非洲草原等等。有些人可能从事盗猎活动，例如为私人收藏家捕捉珍稀动物，或者贩卖受保护的动物和违反道德的动物制品，如兽皮、象牙之类——虽然1920 年代大多数国家这些活动都不算违法。 尽管“王牌猎人”是最典型的类型，不过在加拿大育空的深山老林里打驼鹿和熊为生的土著人也可以算是猎人。
A21: 19 | B21: 书商 | D21: 20-40 | E21: 教育×4 | F21: =EDU*4 -> 0 | G21: 会计，估价，汽车驾驶，历史，图书馆，母语，外语，一项社交技能（取悦、话术、恐吓、说服）。 | H21: 教育 | I21: √ | J21: =IF(I21="√",IF(SUM(J15:J20,J22:J23)>0,2,4),0) -> 4 | K21: 目录学家、其他书商、图书馆和大学、客户。 | M21: 书商可能拥有自己的店面或者利基(小众)邮购服务，也可能辗转全国甚至海外专门经销书籍。许多人拥有富有的，能提供利润丰厚又稀罕的工作的固定客户。
A22: 20 | B22: 赏金猎人 | D22: 9-30 | E22: 教育×2＋力量或敏捷×2 | F22: =EDU*2+MAX(STR*2,DEX*2) -> 0 | G22: 汽车驾驶，电子学或电气维修，格斗或射击，一项社交技能（取悦、话术、恐吓、说服），法律，心理学，追踪，潜行。 | H22: 意志 | I22: × | J22: =IF(I22="√",2,0) -> 0 | K22: 保释业者，本地警察，线人。 | M22: 赏金猎人捉拿罪犯并将他们交给正义去审判。最常见的情况是受保释人的委托去缉捕逃狱者。赏金猎人们为了自己的猎物可以不择手段，几乎不会考虑其他人的正当权益之类细枝末节的东西。 非法闯入、威胁、肢体暴力，都是赏金猎人屡试不爽的秘技。现在这些秘技还包括了电话窃听、黑客操作和其他的秘密监控。 (译注：所谓保释业者。向法院交纳保释金，可以在审判之前免受收押；若被保释者按时接受审判，法院会退还保释金。保释金数额较大，故有保释业者以提供保释金收取手续费为业。)
A23: 21 | B23: 拳击手、摔跤手 | D23: 9-60 | E23: 教育×2＋力量×2 | F23: =EDU*2+STR*2 -> 0 | G23: 闪避，格斗（斗殴），恐吓，跳跃，心理学，侦查，任意两项其他个人或时代特长。 | H23: 幸运 | I23: × | J23: =IF(I23="√",2,0) -> 0 | K23: 运动会主办者，记者，犯罪组织，专业训练人员。 | M23: 拳击手和摔跤手各分为职业和业余两种。 职业拳击手和职业摔角手的活动由外部利益支持的贸助人安排，并有合同约束。他们还要进行全日制的工作和训练。 业余拳击的竞赛种类非常丰富，同时它也是那些想成为职业拳手的人的训练场。不过也有业余和准职业的选手靠参加黑市拳击赛谋生，举办这些比赛的通常是本地的黑社会或者是从中渔利的庄家。
A24: 22 | B24: 管家、男仆、女仆 | D24: 9-40 | E24: 教育×4 | F24: =EDU*4 -> 0 | G24: 会计或估价，技艺（任一：如烹饪、裁缝、理发），急救，聆听，外语，心理学，侦查，任意一项其他个人或时代特长。 | H24: 计算方式
A25: 23 | B25: 神职人员 | D25: 9-60 | E25: 教育×4 | F25: =EDU*4 -> 0 | G25: 会计，历史，图书馆，聆听，外语，一项社交技能（取悦、话术、恐吓、说服），心理学，任意一项其他技能。 | H25: 所有属性的点数相加 | K25: 教会高层、地方教会、小区领导。 | M25: 神职人员通常担任一个教区的牧师，或是经过分配外出传教，尤其是去国外(见传教士)。 不同的教会工作的侧重点和组织结构各不相同，如天主教会的牧师可能上升到主教、大主教和红衣主教，而一个卫理公会的牧师则会升职到教区主管和主教。 许多神职人员都接受忏悔(不仅仅是天主教)。虽然不能透露忏悔的内容，但是要怎样利用它们就全凭他们自己了。 有些教职人员在教堂接受医生、律师、学者的专业培训。这样的调查员应该选择最符合自己工作的职业模板。
A26: 24 | B26: 程序员、电子工程师（现代） | D26: 10-70 | E26: 教育×4 | F26: =EDU*4 -> 0 | G26: 计算机，电气维修，电子学、图书馆，科学（数学），侦查，任意两项其他个人或时代特长。 | K26: 其他IT 工作者，同事和上司，专业网络小区。 | M26: 计算器程序员通常是设计、编写、测试、调试和维护计算器程序源代码的职业。他们精通从形式逻辑到系统平台(程序运行环境)的各种知识，可能是自由工作者，也可能供职于软件开发部门。 计算器技术人员负责计算器系统和网络的开发和维护工作，经常与其他人员(如项目经理)合作来保证系统的完整稳定和正常提供所需功能。类似的职业还包括数据库管理员、系统管理员、网络管理员、多媒体开发人员、软件工程师、网络管理员等。
A27: 25 | B27: 黑客/骇客（现代） | D27: 10-70 | E27: 教育×4 | F27: =EDU*4 -> 0 | G27: 计算机，电气维修，电子学，图书馆，侦查，一项社交技能（取悦、话术、恐吓、说服），任意两项其他技能。 | K27: 其他IT 工作者，专业网络小区，政治团体，犯罪组织。 | M27: 计算器黑客利用计算器和计算器网络为手段，进行干扰或破坏以达成政治目的(有时被称为“政治黑客”)或获取非法利益。达成目标的手段主要是非法入侵计算器和其他用户帐户，目的则可能包括篡改网页、人肉搜索、盗取身份信息、垃圾邮件炸弹、拒绝服务攻击等等。
A28: 26 | B28: 牛仔 | D28: 9-20 | E28: 教育×2＋力量或敏捷×2 | F28: =EDU*2+MAX(STR*2,DEX*2) -> 0 | G28: 闪避，格斗或射击，急救或自然，跳跃，骑乘，生存（任一），投掷，追踪。 | K28: 本地企业家，州农业部门，牛仔比赛主办者，艺人。 | M28: 牛仔在西部的牧区和牧场工作。有些人拥有自己的牧场，更多的则是在各处打工为生。想赚大钱的牛仔会去冒着丢胳膊少腿乃至送命的危险参加牛仔巡回赛，通过旅行获取名誉。 在1920 年代，一些牛仔能在好莱坞找到西部片替身演员和群众演员的工作，例如怀特·厄普就曾为西部电影担任顾问。在现代，有些牧场也对想要体验一把牛仔生活的游客开放。
A29: 27 | B29: 工匠 | D29: 10-40 | E29: 教育×2＋敏捷×2 | F29: =EDU*2+DEX*2 -> 0 | G29: 会计，技艺（任二），机械维修，自然，侦查，任意两项其他个人或时代特长。 | K29: 本地商人，其他工匠和艺术家。 | M29: 工匠也可能被人叫做师傅或大师，是擅长对各种材料进行手工加工的人。通常都是才能出众的人，有的凭借自己的艺术作品出名，有的则会服务于自己的小区。 可能的行当包括：家具、珠宝、钟表、陶艺、锻造、纺织、书法、裁缝、木工、书籍装裱、玩具制造、彩色玻璃吹制等等。
A30: 28 | B30: 罪犯-刺客 | D30: 30-60 | E30: 教育×2＋力量或敏捷×2 | F30: =EDU*2+MAX(STR*2,DEX*2) -> 0 | G30: 乔装，电气维修，格斗，射击，锁匠，机械维修，潜行，心理学。 | K30: 很少，大都是黑社会的人，人们尽量避免和他们交情过深。 | M30: 杀手是地下世界的冷血夺命者。这是一项严谨的活计，他们从外地受雇杀人，接近目标，果断下手，又迅速离开。杀手通常很难融入社会，因为很多杀手行为总是很刻板，其他人很容易以为他们不近人情。但是另一方面，他们也会结婚生子，在其他方面和普通人没有什么不同。
A31: 29 | B31: 罪犯-银行劫匪 | D31: 5-75 | E31: 教育×2＋力量或敏捷×2 | F31: =EDU*2+MAX(STR*2,DEX*2) -> 0 | G31: 汽车驾驶，电气维修或机械维修，格斗，射击，恐吓，锁匠，操作重型机械，任意一项其他个人或时代特长。 | K31: 同伙(不论是现在还是以前的)，独行罪犯，犯罪组织。 | M31: 罪犯的体格和相貌形形色色，有些是纯粹碰运气伺机行事，比如扒手和暴徒；有些则组成分工明确，会详细调查并制定计划的犯罪组织。后者包括银行劫匪、飞贼、赝造者和诈骗者。 罪犯可能为别人工作，后者通常是“匪帮”或罪犯家族；也可能单打独斗，如果成功的报酬值得去费力冒险，才会和别人搭伙。自由犯罪者则往往被称为抢劫犯、响马贼和江洋大盗。
A32: 30 | B32: 罪犯-打手、暴徒 | D32: 5-30 | E32: 教育×2＋力量×2 | F32: =EDU*2+STR*2 -> 0 | G32: 汽车驾驶，格斗，射击，两项社交技能（取悦、话术、恐吓、说服），心理学，潜行，侦查。 | K32: 犯罪组织，本地执法机构，本地企业。 | M32: 打手、暴徒都是犯罪组织的兵卒。他们被犯罪组织豢养，不过团伙上层出事的时候，倒霉的往往是他们这些喽啰。对于他们来说，嘴紧和忠心属于职业道德。
A33: 31 | B33: 罪犯-窃贼 | D33: 5-40 | E33: 教育×2＋敏捷×2 | F33: =EDU*2+DEX*2 -> 0 | G33: 估价，攀爬，电气维修或机械维修，聆听，锁匠，妙手，潜行，侦查。 | K33: 赃物贩子，其他的盗贼。 | M33: 罪犯的体格和相貌形形色色，有些是纯粹碰运气伺机行事，比如扒手和暴徒；有些则组成分工明确，会详细调查并制定计划的犯罪组织。后者包括银行劫匪、飞贼、赝造者和诈骗者。 罪犯可能为别人工作，后者通常是“匪帮”或罪犯家族；也可能单打独斗，如果成功的报酬值得去费力冒险，才会和别人搭伙。自由犯罪者则往往被称为抢劫犯、响马贼和江洋大盗。
A34: 32 | B34: 罪犯-欺诈师 | D34: 10-65 | E34: 教育×2＋外貌×2 | F34: =EDU*2+APP*2 -> 0 | G34: 估价，技艺（表演），法律或外语，聆听，两项社交技能（取悦、话术、恐吓、说服），心理学，妙手。 | K34: 其他的诈骗师，独行罪犯。 | M34: 欺诈师通常都是油嘴滑舌的人物。他们或单独或集体出没在富裕的人家和小区周边，诈取他们来之不易的钱财。许多骗局覆杂精妙，诈骗团伙会倾巢出动乃至租用建筑；有些则不需要这么麻烦，只要一个骗子几分钟就能搞定。
A35: 33 | B35: 罪犯-独行罪犯 | D35: 5-65 | E35: 教育×2＋敏捷或外貌×2 | F35: =EDU*2+MAX(DEX*2,APP*2) -> 0 | G35: 技艺（表演）或乔装，估价，一项社交技能（取悦、话术、恐吓、说服），格斗或射击，锁匠或机械维修，潜行，心理学，侦查。 | K35: 轻罪罪犯，本地执法机构。 | M35: 罪犯的体格和相貌形形色色，有些是纯粹碰运气伺机行事，比如扒手和暴徒；有些则组成分工明确，会详细调查并制定计划的犯罪组织。后者包括银行劫匪、飞贼、赝造者和诈骗者。 罪犯可能为别人工作，后者通常是“匪帮”或罪犯家族；也可能单打独斗，如果成功的报酬值得去费力冒险，才会和别人搭伙。自由犯罪者则往往被称为抢劫犯、响马贼和江洋大盗。
A36: 34 | B36: 罪犯-女飞贼（古典） | D36: 10-80 | E36: 教育×2＋外貌×2 | F36: =EDU*2+APP*2 -> 0 | G36: 技艺（任意），两项社交技能（取悦、话术、恐吓、说服），格斗（斗殴）或射击（手枪），汽车驾驶，聆听，潜行，任意一项其他个人或时代特长。 | K36: 黑帮，执法机构，本地企业 | M36: 女飞贼是名为专业大盗的女人。大部分都是独立行动，也有对自己的男伴言听计从的时候。 不过这也不一定，实际上情况可能完全相反，她完全可以在干了某一票以后就卷走所有现金和皮草溜之大吉。
A37: 35 | B37: 罪犯-赃物贩子 | D37: 20-40 | E37: 教育×2＋外貌×2 | F37: =EDU*2+APP*2 -> 0 | G37: 会计，估价，技艺（伪造），历史，一项社交技能（取悦、话术、恐吓、说服），图书馆，侦查，任意一项其他技能。 | K37: 犯罪组织，贸易伙伴，黑市和和守法的买主。 | M37: 赃物贩子，顾名思义是买卖偷抢来的财产，通常是收购赃物并转手卖给其他罪犯或(无意中)守法的顾客。主要来说，他们是小偷和买家的中间人，有时也会从交易中收取提成；不过更常见的还是以极低的价格直接收购赃物。
A38: 36 | B38: 罪犯-赝造者 | D38: 20-60 | E38: 教育×4 | F38: =EDU*4 -> 0 | G38: 会计，估价，技艺（伪造），历史，图书馆，侦查，妙手，任意一项其他个人或时代特长（如计算机）。 | K38: 犯罪组织，商人。 | M38: 赝造者是地下世界的艺术家，专门从事伪造官方文件、契约、转让书，并提供伪造的签名。初学者只能做做小贼的假身份证，而顶级的赝造者连印假币的铸模都能做。
A39: 37 | B39: 罪犯-走私者 | D39: 20-60 | E39: 教育×2＋外貌或敏捷×2 | F39: =EDU*2+MAX(DEX*2,APP*2) -> 0 | G39: 射击，聆听，导航，一项社交技能（取悦、话术、恐吓、说服），汽车驾驶或驾驶（飞行器或船），心理学，妙手，侦查。 | K39: 犯罪组织，海岸卫队，海关官员。 | M39: 走私一直是一个有利可图的高风险行当。走私者往往有一个合法的表面职业，比如船长、飞行员或商人，以掩盖他们非法运输的行为。
A40: 38 | B40: 罪犯-混混 | D40: 3-10 | E40: 教育×2＋力量或敏捷×2 | F40: =EDU*2+MAX(STR*2,DEX*2) -> 0 | G40: 攀爬，一项社交技能（取悦、话术、恐吓、说服），格斗，射击，跳跃，妙手，潜行，投掷。 | K40: 其他轻罪罪犯，其他混混，本地的赃物贩子，黑帮，当然还有警察。 | M40: 街头混混一般都是些小年轻，弄不好还在寻觅加入真正黑帮的契机。不过他们的本事也就限于偷车，盗窃商店货物，抢钱或者夜盗。
...

Sheet 成长表（测试）
C1: 技能成长表 | F1: 这个表仅作为额外内容，起到辅助记录作用
A2: 技能 | B2: 成长+初始 | C2: 总计成长 | D2: 初始 | E2: 示例 | F2: 模组2 | G2: 模组3 | H2: 模组4 | I2: 模组5 | J2: 模组6 | K2: 模组7 | L2: 模组8 | M2: 模组9 | N2: 模组10 | O2: 模组11 | P2: 模组12 | Q2: 模组13 | R2: 模组14 | S2: 模组15 | T2: 模组16 | U2: 模组17 | V2: 模组18 | W2: 模组19 | X2: 模组20 | Y2: 模组21 | Z2: 模组22 | AA2: 模组23 | AB2: 模组24 | AC2: 模组25 | AD2: 模组26 | AE2: 模组27 | AF2: 模组28 | AG2: 模组29 | AH2: 模组30 | AI2: 模组31 | AJ2: 模组32 | AK2: 模组33 | AL2: 模组34 | AM2: 模组35 | AN2: 模组36 | AO2: 模组37 | AP2: 模组38 | AQ2: 模组39 | AR2: 模组40 | AS2: 模组41 | AT2: 模组42 | AU2: 模组43 | AV2: 模组44 | AW2: 模组45 | AX2: 模组46 | AY2: 模组47 | AZ2: 模组48 | BA2: 模组49 | BB2: 模组50 | BC2: 模组51 | BD2: 模组52 | BE2: 模组53 | BF2: 模组54 | BG2: 模组55 | BH2: 模组56 | BI2: 模组57 | BJ2: 模组58 | BK2: 模组59 | BL2: 模组60 | BM2: 模组61 | BN2: 模组62 | BO2: 模组63 | BP2: 模组64 | BQ2: 模组65 | BR2: 模组66 | BS2: 模组67 | BT2: 模组68 | BU2: 模组69 | BV2: 模组70 | BW2: 模组71 | BX2: 模组72 | BY2: 模组73 | BZ2: 模组74 | CA2: 模组75 | CB2: 模组76 | CC2: 模组77 | CD2: 模组78 | CE2: 模组79 | CF2: 模组80 | CG2: 模组81 | CH2: 模组82 | CI2: 模组83 | CJ2: 模组84 | CK2: 模组85 | CL2: 模组86 | CM2: 模组87 | CN2: 模组88 | CO2: 模组89 | CP2: 模组90 | CQ2: 模组91 | CR2: 模组92 | CS2: 模组93 | CT2: 模组94 | CU2: 模组95 | CV2: 模组96 | CW2: 模组97 | CX2: 模组98 | CY2: 模组99 | CZ2: 模组100
A3: 会计 | B3: =C3+D3 -> 5 | C3: =SUM(E3:CZ3) -> 0 | D3: 5 | E3: 此处填入成长数值
A4: 人类学 | B4: =C4+D4 -> 1 | C4: =SUM(E4:CZ4) -> 0 | D4: 1 | E4: 后面依次类推哦
A5: 估价 | B5: =C5+D5 -> 5 | C5: =SUM(E5:CZ5) -> 0 | D5: 5 | E5: 0
A6: 考古学 | B6: =C6+D6 -> 1 | C6: =SUM(E6:CZ6) -> 0 | D6: 1 | E6: 0
A7: 技艺① | B7: =C7+D7 -> 5 | C7: =SUM(E7:CZ7) -> 0 | D7: 5 | E7: 0
A8: 技艺② | B8: =C8+D8 -> 5 | C8: =SUM(E8:CZ8) -> 0 | D8: 5 | E8: 如果需要补充成长属性的相关经历
A9: 技艺③ | B9: =C9+D9 -> 5 | C9: =SUM(E9:CZ9) -> 0 | D9: 5
A10: 取悦 | B10: =C10+D10 -> 15 | C10: =SUM(E10:CZ10) -> 0 | D10: 15
A11: 攀爬 | B11: =C11+D11 -> 20 | C11: =SUM(E11:CZ11) -> 0 | D11: 20 | E11: 可以解锁工作表后右键单元格
A12: 计算机使用 Ω | B12: =C12+D12 -> 5 | C12: =SUM(E12:CZ12) -> 0 | D12: 5 | E12: 添加批注
A13: 信用评级 | B13: =C13+D13 -> 0 | C13: =SUM(E13:CZ13) -> 0 | D13: 0 | E13: 就像这样，点击此单元格可以看到批注
A14: 克苏鲁神话 | B14: =C14+D14 -> 0 | C14: =SUM(E14:CZ14) -> 0 | D14: 0
A15: 乔装 | B15: =C15+D15 -> 5 | C15: =SUM(E15:CZ15) -> 0 | D15: 5 | E15: 有些时候我们的属性没有发生变化
A16: 闪避 | B16: =C16+D16 -> 0 | C16: =SUM(E16:CZ16) -> 0 | D16: 0 | E16: 但也影响了调查员
A17: 汽车驾驶 | B17: =C17+D17 -> 20 | C17: =SUM(E17:CZ17) -> 0 | D17: 20
A18: 电气维修 | B18: =C18+D18 -> 10 | C18: =SUM(E18:CZ18) -> 0 | D18: 10
A19: 电子学 Ω | B19: =C19+D19 -> 1 | C19: =SUM(E19:CZ19) -> 0 | D19: 1 | E19: 此类内容可移动至该表格的最下方进行描述
A20: 话术 | B20: =C20+D20 -> 5 | C20: =SUM(E20:CZ20) -> 0 | D20: 5
A21: 格斗：斗殴 | B21: =C21+D21 -> 25 | C21: =SUM(E21:CZ21) -> 0 | D21: 25
A22: 格斗① | B22: =C22+D22 -> 0 | C22: =SUM(E22:CZ22) -> 0 | D22: 0
A23: 格斗② | B23: =C23+D23 -> 0 | C23: =SUM(E23:CZ23) -> 0 | D23: 0
A24: 格斗③ | B24: =C24+D24 -> 0 | C24: =SUM(E24:CZ24) -> 0 | D24: 0
A25: 射击：手枪 | B25: =C25+D25 -> 20 | C25: =SUM(E25:CZ25) -> 0 | D25: 20
A26: 射击① | B26: =C26+D26 -> 25 | C26: =SUM(E26:CZ26) -> 0 | D26: 25
A27: 射击② | B27: =C27+D27 -> 0 | C27: =SUM(E27:CZ27) -> 0 | D27: 0
A28: 射击③ | B28: =C28+D28 -> 0 | C28: =SUM(E28:CZ28) -> 0 | D28: 0
A29: 急救 | B29: =C29+D29 -> 30 | C29: =SUM(E29:CZ29) -> 0 | D29: 30
A30: 历史 | B30: =C30+D30 -> 5 | C30: =SUM(E30:CZ30) -> 0 | D30: 5
A31: 恐吓 | B31: =C31+D31 -> 15 | C31: =SUM(E31:CZ31) -> 0 | D31: 15
... A68: 学识： | B68: =C68+D68 -> 1 | C68: =SUM(E68:CZ68) -> 0 | D68: 1
A69: 自定义技能 | B69: =C69+D69 -> 0 | C69: =SUM(E69:CZ69) -> 0
A70: 自定义技能 | B70: =C70+D70 -> 0 | C70: =SUM(E70:CZ70) -> 0
A71: STR | B71: =C71+D71 -> 0 | C71: =SUM(E71:CZ71) -> 0
A72: CON | B72: =C72+D72 -> 0 | C72: =SUM(E72:CZ72) -> 0
A73: SIZ | B73: =C73+D73 -> 0 | C73: =SUM(E73:CZ73) -> 0
A74: DEX | B74: =C74+D74 -> 0 | C74: =SUM(E74:CZ74) -> 0
